Workbook
Name Acc_Brand: '11. Accessories'!$B$3:$B$4
Name Acc_Link: '11. Accessories'!$S$3:$S$4
Name Acc_Mass: '11. Accessories'!$K$3:$K$4
Name Acc_Model: '11. Accessories'!$D$3:$D$4
Name Acc_Price: '11. Accessories'!$R$3:$R$4
Name Bat_Brand: '9. Batteries'!$B$3:$B$19
Name Bat_Link: '9. Batteries'!$P$3:$P$19
Name Bat_Mass: '9. Batteries'!$L$3:$L$19
Name Bat_Model: '9. Batteries'!$C$3:$C$19
Name Bat_Price: '9. Batteries'!$M$3:$M$19
Name Cam_Brand: #REF!
Name Cam_Link: '5. Cameras'!$K$3:$K$9
Name Cam_Mass: #REF!
Name Cam_Model: #REF!
Name Cam_Price: #REF!
Name Camera_Brand: '5. Cameras'!$B$3:$B$9
Name Camera_Model: '5. Cameras'!$C$3:$C$9
Name Camera_Price: '5. Cameras'!$J$3:$J$9
Name ESC_Brand: '8. ESCs'!$B$3:$B$25
Name ESC_Link: '8. ESCs'!$K$3:$K$30
Name ESC_Mass: '8. ESCs'!$H$3:$H$25
Name ESC_Model: '8. ESCs'!$E$3:$E$25
Name ESC_Model2: '8. ESCs'!$C$3:$C$25
Name ESC_Model3: '8. ESCs'!$C$3:$C$30
Name ESC_Price: '8. ESCs'!$J$3:$J$25
Name FC_Brand: '2. Flight Controllers'!$B$3:$B$9
Name FC_Link: '2. Flight Controllers'!$K$3:$K$9
Name FC_Mass: '2. Flight Controllers'!$I$3:$I$9
Name FC_Model: '2. Flight Controllers'!$C$3:$C$9
Name FC_Price: '2. Flight Controllers'!$J$3:$J$9
Name Frame_Brand: '1. Multirotor Frames'!$B$3:$B$23
Name Frame_Line: '1. Multirotor Frames'!$C$3:$C$23
Name Frame_Link: '1. Multirotor Frames'!$Q$3:$Q$23
Name Frame_Mass: '1. Multirotor Frames'!$F$3:$F$23
Name Frame_Model: '1. Multirotor Frames'!$D$3:$D$23
Name Frame_Price: '1. Multirotor Frames'!$P$3:$P$23
Name Framemass: '1. Multirotor Frames'!$F$3:$F$23
Name Gimbal_Brand: '6. Gimbals'!$H$5
Name Gimbal_Brand2: '6. Gimbals'!$B$3:$B$10
Name Gimbal_Link: '6. Gimbals'!$I$3:$I$10
Name Gimbal_Mass: '6. Gimbals'!$G$3:$G$10
Name Gimbal_Model: '6. Gimbals'!$C$3:$C$10
Name Gimbal_Price: '6. Gimbals'!$H$3:$H$10
Name Motor_Brand: '7. Motors'!$B$2:$B$49
Name Motor_Link: '7. Motors'!$S$2:$S$49
Name Motor_Mass: '7. Motors'!$P$2:$P$49
Name Motor_Model: '7. Motors'!$D$2:$D$49
Name Motor_Price: '7. Motors'!$R$2:$R$49
Name Number_of_Motors: '1. Multirotor Frames'!$E$3:$E$23
Name Prop_Brand: '10. Propellers'!$B$3:$B$30
Name Prop_Link: '10. Propellers'!$M$3:$M$30
Name Prop_Mass: '10. Propellers'!$I$3:$I$30
Name Prop_Model: '10. Propellers'!$D$3:$D$30
Name Prop_Price: '10. Propellers'!$K$3:$K$30
Name RC_Brand: '4. Receivers'!$B$3:$B$12
Name RC_Link: '4. Receivers'!$L$3:$L$12
Name RC_Mass: '4. Receivers'!$J$3:$J$12
Name RC_Model: '4. Receivers'!$B$3:$B$12
Name RC_Model2: '4. Receivers'!$D$3:$D$12
Name RC_Price: '4. Receivers'!$K$3:$K$12

Sheet BOM Summary
A2: ITEM NO. | B2: CATEGORY | C2: COMPONENT | D2: BRAND | E2: DROP DOWNS: | F2: QTY. | G2: MASS EACH (g) | H2: TOTAL MASS (g) | I2: PRICE EACH | J2: TOTAL PRICE | K2: LINK
A3: 1 | B3: Hardware | C3: Multirotor | D3: =INDEX(Frame_Brand,MATCH(E3,Frame_Model,0)) -> Tarot | E3: TL960A | F3: 1 | G3: =INDEX(Frame_Mass,MATCH(E3,Frame_Model,0)) -> 1050 | H3: =G3*F3 -> 1050 | I3: =INDEX(Frame_Price,MATCH(E3,Frame_Model,0)) -> 444 | J3: =I3*F3 -> 444 | K3: =INDEX(Frame_Link,MATCH(E3,Frame_Model,0)) -> www.myrcmodel.com
A4: 2 | B4: Electronics | C4: Flight Contoller | D4: =INDEX(FC_Brand,MATCH(E4,FC_Model,0)) -> 3DRobotics | E4: Pixhawk | F4: 1 | G4: =INDEX(FC_Mass,MATCH(E4,FC_Model,0)) -> 38 | H4: =G4*F4 -> 38 | I4: =INDEX(FC_Price,MATCH(E4,FC_Model,0)) -> 379.98 | J4: =I4*F4 -> 379.98 | K4: =INDEX(FC_Link,MATCH(E4,FC_Model,0)) -> https://store.3drobotics.com
A5: 3 | B5: Electronics | C5: Transmitter | D5: =INDEX(Tx_Brand,MATCH(E5,Tx_Model,0)) -> Futaba | E5: T8FG Super | F5: 1 | G5: 0 | H5: 0 | I5: =INDEX(Tx_Price,MATCH(E5,Tx_Model,0)) -> 479 | J5: =I5*F5 -> 479 | K5: =INDEX(Tx_Link,MATCH(E5,Tx_Model,0)) -> http://www.futaba-rc.com/systems/futk8010.html
A6: 4 | B6: Electronics | C6: Receiver | D6: =INDEX(RC_Brand,MATCH(E6,RC_Model2,0)) -> Futaba | E6: R6208SB | F6: 1 | G6: =INDEX(RC_Mass,MATCH(E6,RC_Model2,0)) -> 13.8 | H6: =G6*F6 -> 13.8 | I6: =INDEX(RC_Price,MATCH(E6,RC_Model2,0)) -> 129.99 | J6: =I6*F6 -> 129.99 | K6: =INDEX(RC_Link,MATCH(E6,RC_Model2,0)) -> www.gpdealera.com
A7: 5 | B7: Electronics | C7: Camera | D7: =INDEX(Camera_Brand,MATCH(E7,Camera_Model,0)) -> Cannon | E7: 5D Mark III with 24mm f/2.8 | F7: 1 | G7: =INDEX('5. Cameras'!I3:I9,MATCH(E7,Camera_Model,0)) -> 1244 | H7: =G7*F7 -> 1244 | I7: =INDEX(Camera_Price,MATCH(E7,Camera_Model,0)) -> 3399 | J7: =I7*F7 -> 3399 | K7: =INDEX(Cam_Link,MATCH(E7,Camera_Model,0)) -> www.usa.canon.com
A8: 6 | B8: Electronics | C8: Gimbal | D8: =INDEX(Gimbal_Brand2,MATCH(E8,Gimbal_Model,0)) -> DJI | E8: Z15 - 5D | F8: 1 | G8: =INDEX(Gimbal_Mass,MATCH(E8,Gimbal_Model,0)) -> 1420 | H8: =G8*F8 -> 1420 | I8: =INDEX(Gimbal_Price,MATCH(E8,Gimbal_Model,0)) -> 2999 | J8: =I8*F8 -> 2999 | K8: =INDEX(Gimbal_Link,MATCH(E8,Gimbal_Model,0)) -> www.dji.com
A9: 7 | B9: Electronics | C9: Motor | D9: =INDEX(Motor_Brand,MATCH(E9,Motor_Model,0)) -> Tiger | E9: U3-700 | F9: =INDEX(Number_of_Motors, MATCH(E3,Frame_Model,0)) -> 6 | G9: =INDEX(Motor_Mass,MATCH(E9,Motor_Model,0)) -> 97 | H9: =G9*F9 -> 582 | I9: =INDEX(Motor_Price,MATCH(E9,Motor_Model,0)) -> 109.9 | J9: =I9*F9 -> 659.4 | K9: =INDEX(Motor_Link,MATCH(E9,Motor_Model,0)) -> www.rctigermotor.com
A10: 8 | B10: Electronics | C10: ESC | D10: =INDEX(ESC_Brand,MATCH(E10,ESC_Model2,0)) -> T-Motor | E10: T 40 | F10: =F9 -> 6 | G10: =INDEX(ESC_Mass,MATCH(E10,ESC_Model2,0)) -> 35 | H10: =G10*F10 -> 210 | I10: =INDEX(ESC_Price,MATCH(E10,ESC_Model2,0)) -> 45.99 | J10: =I10*F10 -> 275.94 | K10: =INDEX(ESC_Link,MATCH(E10,ESC_Model3,0)) -> http://www.rctigermotor.com/html/2013/esc_0916/84.html
A11: 9 | B11: Electronics | C11: Battery | D11: =INDEX(Bat_Brand,MATCH(E11,Bat_Model,0)) -> Turnigy | E11: nano-tech 5000mAh 4S 65C | F11: 2 | G11: =INDEX(Bat_Mass,MATCH(E11,Bat_Model,0)) -> 576 | H11: =G11*F11 -> 1152 | I11: =INDEX(Bat_Price,MATCH(E11,Bat_Model,0)) -> 76.59 | J11: =I11*F11 -> 153.18 | K11: =INDEX(Bat_Link,MATCH(E11,Bat_Model,0)) -> http://www.hobbyking.com
A12: 10 | B12: Hardware | C12: Propellers | D12: =INDEX(Prop_Brand,MATCH(E12,Prop_Model,0)) -> GemFan | E12: 15x5.5 | F12: 5 | G12: =INDEX(Prop_Mass,MATCH(E12,Prop_Model,0)) -> 16.4 | H12: =G12*$F$9 -> 98.4 | I12: =INDEX(Prop_Price,MATCH(E12,Prop_Model,0)) -> 40 | J12: =I12*F12 -> 200 | K12: =INDEX(Prop_Link,MATCH(E12,Prop_Model,0)) -> http://www.rc-drones.com/gemfan-S800-Prop.php
A13: 11 | B13: Hardware | C13: Accessories | D13: =INDEX(Acc_Brand,MATCH(E13,Acc_Model,0)) -> Spot | E13: Trace | F13: 1 | G13: =INDEX(Acc_Mass,MATCH(E13,Acc_Model,0)) -> 88 | H13: =G13*F13 -> 88 | I13: =INDEX(Acc_Price,MATCH(E13,Acc_Model,0)) -> 199.84 | J13: =I13*F13 -> 199.84 | K13: =INDEX(Acc_Link,MATCH(E13,Acc_Model,0)) -> www.findmespot.com
A14: TOTALS | E14: # of Parts: | F14: =SUM(F3:F13) -> 14 | G14: Mass: | H14: =SUM(H3:H13) -> 5896.2 | I14: Price: | J14: =SUM(J3:J13) -> 9319.33
A15: =NOW() -> 41741.599 | I15: Less what I already own: | J15: =J14-J5-J7 -> 5441.33
A16: Round 0: | E16: Round 1 | F16: Round 2 | G16: Round 3 | H16: Round 4
A17: ITEM NO. | B17: CATEGORY | C17: COMPONENT | D17: OPTIONS | E17: 4/5/14 11:15AM | F17: 4/7/14 8:51PM | G17: 41738.542
A18: 1 | B18: Frame | C18: Multirotor | D18: 21 | E18: 9 | F18: 3 | G18: 1 | H18: 1 | K18: Component Selected During:
A19: 2 | B19: Electronics | C19: Flight Contoller | D19: 7 | E19: 5 | F19: 3 | G19: 1 | H19: 1 | K19: Round 1 (4 items)
A20: 3 | B20: Electronics | C20: Transmitter | D20: 13 | E20: 1 | F20: 1 | G20: 1 | H20: 1 | K20: Round 2 (0 items)
A21: 4 | B21: Electronics | C21: Receiver | D21: 8 | E21: 1 | F21: 1 | G21: 1 | H21: 1 | K21: Round 3 (3 Items)
A22: 5 | B22: Accessories | C22: Camera | D22: 7 | E22: 1 | F22: 1 | G22: 1 | H22: 1 | K22: Round 4 (? Items)
A23: 6 | B23: Accessories | C23: Gimbal | D23: 7 | E23: 5 | F23: 3 | G23: 1 | H23: 1
A24: 7 | B24: Electronics | C24: Motor | D24: 37 | E24: 20 | F24: 15 | G24: 11
A25: 8 | B25: Electronics | C25: ESC | D25: 23 | E25: 23 | F25: 17 | G25: 10
A26: 9 | B26: Electronics | C26: Battery | D26: 17 | E26: 17 | F26: 11 | G26: 7
A27: 10 | B27: Hardware | C27: Propellers | D27: 28 | E27: 28 | F27: 20 | G27: 20
A28: 11 | B28: Accessories | C28: GPS Tracker | D28: 1 | E28: 1 | F28: 1 | G28: 1 | H28: 1
C29: # OF TOTAL POSSIBLE COMBINATIONS: | D29: =D18*D19*D20*D21*D22*D23*D24*D25*D26*D27 -> 303447292512 | E29: =E18*E19*E20*E21*E22*E23*E24*E25*E26*E27 -> 49266000 | F29: =F18*F19*F20*F21*F22*F23*F24*F25*F26*F27 -> 1514700 | G29: =G18*G19*G20*G21*G22*G23*G24*G25*G26*G27 -> 15400 | H29: =H18*H19*H20*H21*H22*H23*H24*H25*H26*H27 -> 0
D30: % reduction | E30: =(1-(49266000/D29))*100 -> 99.983765 | F30: =(1-(F29/E29))*100 -> 96.925466 | G30: =(1-(G29/F29))*100 -> 98.983297 | H30: =(1-(H29/G29))*100 -> 100
A32: This Round
A33: ITEM NO. | B33: CATEGORY | C33: COMPONENT | D33: OPTIONS
A34: 1 | B34: Hardware | C34: Multirotor | D34: ='1. Multirotor Frames'!A23 -> 1
A35: 2 | B35: Electronics | C35: Flight Contoller | D35: ='2. Flight Controllers'!A9 -> 1
A36: 3 | B36: Electronics | C36: Transmitter | D36: ='3. Transmitters'!A17 -> 1
A37: 4 | B37: Electronics | C37: Receiver | D37: ='4. Receivers'!A12 -> 1
A38: 5 | B38: Accessories | C38: Camera | D38: ='5. Cameras'!A9 -> 1
A39: 6 | B39: Accessories | C39: Gimbal | D39: ='6. Gimbals'!A10 -> 1
A40: 7 | B40: Electronics | C40: Motor | D40: ='7. Motors'!A49 -> 10
A41: 8 | B41: Electronics | C41: ESC | D41: ='8. ESCs'!A30 -> 10
A42: 9 | B42: Electronics | C42: Battery | D42: ='9. Batteries'!A19 -> 7
...

Sheet Budget
A1: Date | B1: Account Balance | C1: Disbursable Balance
A2: 41736 | B2: 4638.46 | C2: -253.2
B3: =B2-800 -> 3838.46
B4: =B3-699 -> 3139.46

Sheet 1. Multirotor Frames
A1: Multirotor Frames
A2: Option | B2: Brand | C2: Line | D2: Model | E2: # of Motors | F2: Frame Mass (g) | G2: Between Motor Centers (mm) | H2: Between Motor Centers (in) | I2: Material | J2: Country of Origin | K2: Retractable Landing Gear Option? | L2: Max Propeller Size | M2: Foldable? | N2: Stock Frame Fits Gimbal? | O2: Payload Limit (KG) | P2: Price (US$) | Q2: Link
A3: 21 | B3: Aeronavics | C3: Airframe | D3: XM-6 Ti-QR | E3: 6 | F3: ? | G3: 770 | H3: =G3/25.4 -> 30.314961 | I3: CF | J3: New Zealand | K3: Y | L3: 14 | M3: Y | N3: Y | O3: ? | P3: 1922.69 | Q3: www.aeronavics.com
B4: Aeronavics | C4: Airframe | D4: XM-8 Ti-QR | E4: 8 | F4: 2415 | G4: 940 | H4: =G4/25.4 -> 37.007874 | I4: CF | J4: New Zealand | K4: Y | L4: 13 | M4: Y | N4: Y | O4: ? | P4: 2091.57 | Q4: www.aeronavics.com
B5: Aeronavics | C5: SkyJib | D5: 6 Ti-QR | E5: 6 | F5: ? | G5: 1080 | H5: =G5/25.4 -> 42.519685 | I5: CF | J5: New Zealand | K5: Y | L5: 17 | M5: Y | N5: Y | O5: ? | P5: 2684.83 | Q5: www.aeronavics.com
B6: Aeronavics | C6: SkyJib | D6: 8 Ti-QR | E6: 8 | F6: ? | G6: 1160 | H6: =G6/25.4 -> 45.669291 | I6: CF | J6: New Zealand | K6: Y | L6: 15 | M6: Y | N6: Y | O6: ? | P6: 3057.25 | Q6: www.aeronavics.com
B7: Aeronavics | C7: SkyJib | D7: X4 Ti-QR | E7: 8 | F7: ? | G7: 900 | H7: =G7/25.4 -> 35.433071 | I7: CF | J7: New Zealand | K7: Y | L7: 15 | M7: Y | N7: Y | O7: ? | P7: 2702.15 | Q7: www.aeronavics.com
B8: Arris | C8: Hexacopter | D8: M1000 | E8: 6 | F8: ? | G8: 1000 | H8: =G8/25.4 -> 39.370079 | I8: CF | J8: China | K8: N | L8: ? | M8: N | N8: Y | O8: ? | P8: 350 | Q8: www.hobby-wing.com
B9: Arris | C9: Hexacopter | D9: M1050 | E9: 6 | F9: 1400 | G9: 1050 | H9: =G9/25.4 -> 41.338583 | I9: CF | J9: China | K9: N | L9: 17 | M9: Y | N9: Y | O9: ? | P9: 349 | Q9: www.hobby-wing.com
B10: Arris | C10: Hexacopter | D10: M680 | E10: 6 | F10: ? | G10: 680 | H10: =G10/25.4 -> 26.771654 | I10: CF | J10: China | K10: N | L10: ? | M10: Y | N10: Y | O10: ? | P10: 195 | Q10: www.hobby-wing.com
B11: Carboncore | C11: Hexacopter | D11: Hex 650 | E11: 6 | F11: 720 | G11: 650 | H11: =G11/25.4 -> 25.590551 | I11: CF | J11: United Kingdom | K11: N | L11: ? | M11: N | N11: Y | O11: 6 total | P11: 549 | Q11: www.coptersquad.com
B12: Carboncore | C12: Hexacopter | D12: Hex 950 | E12: 6 | F12: 780 | G12: 950 | H12: =G12/25.4 -> 37.401575 | I12: CF | J12: United Kingdom | K12: N | L12: ? | M12: N | N12: Y | O12: 8 total | P12: 590 | Q12: www.coptersquad.com
B13: Carboncore | C13: Octocopter | D13: X8 650 Quad | E13: 8 | F13: 600 | G13: 650 | H13: =G13/25.4 -> 25.590551 | I13: CF | J13: United Kingdom | K13: N | L13: ? | M13: N | N13: N | O13: ? | P13: 385 | Q13: www.rc-drones.com
B14: Carboncore | C14: Octocopter | D14: X8 950 Quad | E14: 8 | F14: 655 | G14: 950 | H14: =G14/25.4 -> 37.401575 | I14: CF | J14: United Kingdom | K14: N | L14: ? | M14: N | N14: N | O14: ? | P14: 435 | Q14: www.rc-drones.com
B15: Carboncore | C15: X8 Co-Axial | D15: Cortex | E15: 8 | F15: 1230 | G15: 800 | H15: =G15/25.4 -> 31.496063 | I15: CF | J15: United Kingdom | K15: N | L15: ? | M15: Y | N15: Y | O15: ? | P15: 1100 | Q15: www.shop.carboncore.co.uk
B16: DJI | C16: Spreading Wings | D16: S1000 | E16: 8 | F16: 4200 | G16: 1000 | H16: =G16/25.4 -> 39.370079 | I16: CF | J16: China | K16: Y | L16: 15 | M16: Y | N16: Y | O16: 5.8 | P16: 3939 | Q16: www.dji.com
B17: DJI | C17: Spreading Wings | D17: S800 EVO | E17: 6 | F17: 3700 | G17: 800 | H17: =G17/25.4 -> 31.496063 | I17: CF | J17: China | K17: Y | L17: 15 | M17: N | N17: Y | O17: 4.3 | P17: 2999 | Q17: www.dji.com
B18: Tarot | C18: Hexacopter | D18: TL810A | E18: 6 | F18: 1020 | G18: 850 | H18: =G18/25.4 -> 33.464567 | I18: CF | J18: China | K18: N | L18: 15 | M18: Y | N18: Y | O18: 3 | P18: =339+105 -> 444 | Q18: www.myrcmodel.com
B19: Tarot | C19: Hexacopter | D19: TL960A | E19: 6 | F19: 1050 | G19: 960 | H19: =G19/25.4 -> 37.795276 | I19: CF | J19: China | K19: N | L19: 18 | M19: Y | N19: Y | O19: 3.5 | P19: =339+105 -> 444 | Q19: www.myrcmodel.com
B20: Tarot | C20: Octocopter | D20: T15 | E20: 8 | F20: 1950 | G20: 1020 | H20: =G20/25.4 -> 40.15748 | I20: CF | J20: China | K20: N | L20: 15 | M20: Y | N20: Y | O20: 11 total | P20: 619 | Q20: www.myrcmodel.com
B21: Tarot | C21: Hexacopter | D21: FY680 | E21: 6 | F21: 600 | G21: 680 | H21: =G21/25.4 -> 26.771654 | I21: CF | J21: China | K21: N | L21: 13 | M21: Y | N21: Y | O21: ? | P21: 169.99 | Q21: www.myrcmodel.com
B22: Tarot | C22: Hexacopter | D22: FY690S | E22: 6 | F22: 600 | G22: 690 | H22: =G22/25.4 -> 27.165354 | I22: CF | J22: China | K22: N | L22: 13 | M22: Y | N22: Y | O22: ? | P22: 199 | Q22: www.myrcmodel.com
A23: 1 | B23: Tarot | C23: Octocopter | D23: IRON MAN 1000 | E23: 8 | F23: 1500 | G23: 1020 | H23: =G23/25.4 -> 40.15748 | I23: CF | J23: China | K23: N | L23: 15 | M23: N | N23: Y | O23: 8 | P23: 399 | Q23: www.myrcmodel.com
E24: Minimums: | F24: =MIN(F3:F23) -> 600 | G24: =MIN(G3:G23) -> 650 | H24: =MIN(H3:H23) -> 25.590551 | L24: =MIN(L3:L23) -> 13 | P24: =MIN(P8:P14,P18:P23) -> 169.99 | Q24: =NOW() -> 41741.599
E25: Maximums: | F25: =MAX(F3:F23) -> 4200 | G25: =MAX(G3:G23) -> 1160 | H25: =MAX(H3:H23) -> 45.669291 | L25: =MAX(L3:L23) -> 18 | P25: =MAX(P8:P14,P18:P23) -> 619
E26: Averages: | F26: =AVERAGE(Frame_Mass) -> 1494.6667 | G26: =AVERAGE(G3:G23) -> 885.71429 | H26: =AVERAGE(H3:H23) -> 34.870641 | L26: =AVERAGE(L3:L23) -> 15 | P26: =AVERAGE(P8:P14,P18:P23) -> 394.46077
B27: Elimination
B28: Round 1: | C28: Round 2: | D28: Round 3:
B29: High Price | C29: 8 Motors | D29: Too Heavy
B30: Small Size | C30: Not Foldable | D30: Payload < 3.5
B32: Selected

Sheet 2. Flight Controllers
A1: Flight Controllers
A2: Option | B2: Brand | C2: Model | D2: GPS included? | E2: LED included? | F2: Gimbal Compatible? | G2: Program via computer? | H2: # of Battery Cells: | I2: Mass (g) | J2: Price (US$) | K2: Link
A3: 7 | B3: 3DRobotics | C3: APM 2.6 Set | D3: ? | E3: N | F3: Y | G3: ? | H3: ? | I3: 0 | J3: 339.98 | K3: https://store.3drobotics.com
A4: 1 | B4: 3DRobotics | C4: Pixhawk | D4: ? | E4: N | F4: Y | G4: ? | H4: ? | I4: 38 | J4: 379.98 | K4: https://store.3drobotics.com
B5: DJI | C5: A2 | D5: Y | E5: Y | F5: Y | G5: Y | H5: 2 - 6 | I5: 224 | J5: 1299 | K5: http://www.dji.com/product/a2
B6: DJI | C6: Naza-M V2 | D6: Y | E6: Y | F6: Y | G6: Y | H6: 2 - 6 | I6: 95 | J6: 299 | K6: http://www.dji.com/product/naza-m-v2
B7: DJI | C7: Wookong-M | D7: Y | E7: ? | F7: Y | G7: Y | H7: 2 - 6 | I7: 118 | J7: 999 | K7: http://www.dji.com/product/wookong-m
B8: Feiyu Tech | C8: FY41AP GPS & OSD | D8: Y | E8: N | F8: Y | G8: Y | H8: 2 - 6 | I8: 220 | J8: 412 | K8: http://www.coptersquad.com
A9: 1 | B9: Feiyu Tech | C9: FYDosAutopilot | D9: ? | E9: N | F9: Y | G9: Y | I9: 220 | J9: 275 | K9: http://www.coptersquad.com
H10: Min: | I10: =MIN(FC_Mass) -> 0 | J10: =MIN(FC_Price) -> 275 | K10: =NOW() -> 41741.599
H11: Max: | I11: =MAX(FC_Mass) -> 224 | J11: =MAX(FC_Price) -> 1299
B12: Elimination | H12: Avg: | I12: =AVERAGE(FC_Mass) -> 130.71429 | J12: =AVERAGE(FC_Price) -> 571.99429
B13: Round 1: | C13: Round 2:
B14: High Price | C14: Unfamiliar
B16: Round 3:
B17: Pixhawk is newer
B18: Want to try competitor
B20: Selected

Sheet 3. Transmitters
A1: Transmitters
A2: Option | B2: Brand | C2: Model | D2: Radio Spectrum | E2: # of Channels | F2: Memory Card? | G2: Type | H2: Mode 2 available? | I2: Recommened Receiver | J2: LCD Screen? | K2: Price | L2: Link
A3: 13 | B3: Futaba | C3: 14SG | D3: 2.4GHz | E3: 14 | F3: SD | G3: FASST | H3: Y | I3: R6014HS | J3: Y | K3: 599 | L3: http://www.futaba-rc.com/systems/futk9410-14sg/index.html
A4: 1 | B4: Futaba | C4: T8FG Super | D4: 2.4GHz | E4: 14 | F4: SD | G4: FASST | H4: Y | I4: R6208SB | J4: Y | K4: 479 | L4: http://www.futaba-rc.com/systems/futk8010.html
B5: Futaba | C5: 10CG | D5: 2.4GHz | E5: 10 | F5: ? | G5: FASST | H5: Y | I5: R6014HS | J5: Y | K5: 549.9 | L5: http://www.futaba-rc.com/systems/futk9255.html
B6: Futaba | C6: 7C | D6: 2.4GHz | E6: 7 | F6: None | G6: FASST | H6: Y | I6: R617FS | J6: Y | K6: 279.99 | L6: http://www.futaba-rc.com/systems/futk7000.html
B7: Futaba | C7: 6EX | D7: 2.4GHz | E7: 6 | F7: None | G7: FASST | H7: Y | I7: R617FS | J7: Y | K7: 212.08 | L7: http://www.futaba-rc.com/systems/futk6900.html
B9: JR | C9: XG14 | D9: 2.4GHz | E9: 14 | F9: SD | G9: DMSS | H9: Y | I9: RG1131B | J9: Y | K9: 679 | L9: http://www.jramericas.com/233795/JRP00632/?pcat=2
B10: JR | C10: XG11 | D10: 2.4GHz | E10: 11 | F10: SD | G10: DMSS | H10: Y | I10: RG1131B | J10: Y | K10: 799 | L10: http://www.jramericas.com/211277/JRP00615/?pcat=2
B11: JR | C11: XG8 | D11: 2.4GHz | E11: 8 | F11: SD | G11: DMSS | H11: Y | I11: RG731B | J11: Y | K11: 429 | L11: http://www.jramericas.com/211276/JRP00596/?pcat=2
B12: JR | C12: XG6 | D12: 2.4GHz | E12: 6 | F12: microSD | G12: DMSS | H12: Y | I12: RG631B | J12: Y | K12: 199 | L12: http://www.jramericas.com/211278/JRP00619/?pcat=2
B14: Spektrum | C14: DX9 | D14: 2.4GHz | E14: 9 | F14: SD | G14: DSM2/DSMX | H14: Y | I14: ? | J14: Y | K14: 449.99 | L14: http://www.spektrumrc.com/Products/Default.aspx?ProdId=SPMR9900
B15: Spektrum | C15: DX8 | D15: 2.4GHz | E15: 8 | F15: SD | G15: DSM2/DSMX | H15: Y | I15: ? | J15: Y | K15: 299.99 | L15: http://www.spektrumrc.com/Products/Default.aspx?ProdId=SPMR8810
B16: Spektrum | C16: DX7s | D16: 2.4GHz | E16: 7 | F16: SD | G16: DSM2/DSMX | H16: Y | I16: AR8000 | J16: Y | K16: 299.99 | L16: http://www.spektrumrc.com/Products/Default.aspx?ProdId=SPM7800
A17: 1 | B17: Spektrum | C17: DX6 | D17: 2.4GHz | E17: 6 | F17: SD | G17: DSM2/DSMX | H17: Y | I17: AR610 | J17: Y | K17: 229.99 | L17: http://www.spektrumrc.com/Products/Default.aspx?ProdId=SPM6700
C18: Min: | E18: =MIN(E3:E17) -> 6 | K18: =MIN(K3:K17) -> 199 | L18: =NOW() -> 41741.599
C19: Max: | E19: =MAX(E3:E17) -> 14 | K19: =MAX(K3:K17) -> 799
C20: Avg: | E20: =AVERAGE(E3:E17) -> 9.2307692 | K20: =AVERAGE(K3:K17) -> 423.53308
B22: Elimination
B23: Round 1:
B24: Already Own

Sheet 4. Receivers
A1: Receivers
A2: Option | B2: Brand | C2: Line | D2: Model | E2: # of channels | F2: Length (mm) | G2: Width (mm) | H2: Height (mm) | I2: Operating Voltage | J2: Mass (grams) | K2: Price (US$) | L2: Link
A3: 8 | B3: Futaba | C3: FASST 2.4GHz | D3: R6014HS | E3: 14 | F3: 52 | G3: 37.6 | H3: 15.9 | I3: 4.8-6 | J3: 21.5 | K3: 169.98 | L3: www.gpdealera.com
A4: 1 | B4: Futaba | C4: FASST 2.4GHz | D4: R6208SB | E4: 8 | F4: 47.3 | G4: 24.9 | H4: 14.3 | I4: 3.7-7.4 | J4: 13.8 | K4: 129.99 | L4: www.gpdealera.com
B5: Futaba | C5: FASST 2.4GHz | D5: R617FS | E5: 7 | F5: 40 | G5: 27 | H5: 9 | I5: 4.8-6 | J5: 9.8 | K5: 69.95 | L5: www.gpdealera.com
B7: JR | C7: DMSS 2.4GHz | D7: RG1131B | E7: 11 | F7: 47.5 | G7: 32 | H7: 14 | I7: 4.5-8.5 | J7: 18 | K7: 129.99 | L7: www.horizonhobby.com
B8: JR | C8: DMSS 2.4GHz | D8: RG631B | E8: 6 | F8: 46.5 | G8: 20 | H8: 12.5 | I8: 4.8-8.5 | J8: 9 | K8: 79.99 | L8: www.horizonhobby.com
B10: Spektrum | C10: DSMX 2.4 GHz | D10: AR8000 | E10: 8 | F10: 34.3 | G10: 32.3 | H10: 11.4 | I10: 3.5-9.6 | J10: 9.4 | K10: 129.99 | L10: www.spektrumrc.com
B11: Spektrum | C11: DSMX 2.4 GHz | D11: AR7610 | E11: 7 | F11: 34.3 | G11: 29.2 | H11: 11.4 | I11: 3.5-9.6 | J11: 8.9 | K11: 89.99 | L11: www.spektrumrc.com
A12: 1 | B12: Spektrum | C12: DSMX 2.4 GHz | D12: AR610 | E12: 6 | F12: 36.6 | G12: 26.7 | H12: 12.7 | I12: ? | J12: 9 | K12: 49.99 | L12: www.spektrumrc.com
D13: MIN: | E13: =MIN(E3:E12) -> 6 | F13: =MIN(F3:F12) -> 34.3 | G13: =MIN(G3:G12) -> 20 | H13: =MIN(H3:H12) -> 9 | J13: =MIN(J3:J12) -> 8.9 | K13: =MIN(K3:K12) -> 49.99 | L13: =NOW() -> 41741.599
D14: MAX: | E14: =MAX(E3:E12) -> 14 | F14: =MAX(F3:F12) -> 52 | G14: =MAX(G3:G12) -> 37.6 | H14: =MAX(H3:H12) -> 15.9 | J14: =MAX(J3:J12) -> 21.5 | K14: =MAX(K3:K12) -> 169.98
B15: Elimination | D15: AVG: | E15: =AVERAGE(E3:E12) -> 8.375 | F15: =AVERAGE(F3:F12) -> 42.3125 | G15: =AVERAGE(G3:G12) -> 28.7125 | H15: =AVERAGE(H3:H12) -> 12.65 | J15: =AVERAGE(J3:J12) -> 12.425 | K15: =AVERAGE(K3:K12) -> 106.23375
B16: Round 1:
B17: Recommended for my Tx

Sheet 5. Cameras
A1: Cameras
A2: Option | B2: Brand | C2: Model | D2: MegaPixals | E2: Photo? | F2: Video? | G2: Memory Card | H2: Custom Gimbal Available | I2: Mass (grams) | J2: Price (US$) | K2: Link
A3: 7 | B3: Black Magic | C3: Pocket Cinema Cam | D3: 12 | E3: Y | F3: 1080 @ 30fps | G3: SD | H3: Z15 | I3: 355 | J3: 995 | K3: bhphotovideo.com
B4: Cannon | C4: 5D Mark III with 24mm f/2.8 | D4: 22.3 | E4: Y | F4: at? | G4: SD | H4: Z15 | I4: 1244 | J4: 3399 | K4: www.usa.canon.com
A5: 1 | B5: GoPro | C5: Hero 3+ Black | D5: 12 | E5: Y | F5: at? | G5: Micro SD | H5: H3-3D | I5: 74 | J5: 399.99 | K5: http://gopro.com/cameras/hd-hero3-black-edition
B6: GoPro | C6: Hero 3+ Silver | D6: 10 | E6: Y | F6: at? | G6: Micro SD | H6: H3-3D | I6: 74 | J6: 299.99 | K6: http://gopro.com/cameras/hd-hero3-silver-edition
B7: Nikon | C7: D300 | D7: 12.3 | E7: Y | F7: N/A | G7: CF | H7: AV200 | I7: 840 | J7: 1596.95 | K7: bhphotovideo.com
B8: Nikon | C8: D800 | D8: 36.3 | E8: Y | F8: 1080 @ 30fps | G8: SD | H8: AV200 | I8: 900 | J8: 2799.95 | K8: www.nikonusa.com
A9: 1 | B9: Panasonic | C9: GH3 | D9: 16 | E9: Y | F9: 1080 @ 60fps | G9: SD | H9: AV130 | I9: 550 | J9: 1298 | K9: bhphotovideo.com
C10: Min: | D10: =MIN(D3:D9) -> 10 | I10: =MIN(I3:I9) -> 74 | J10: =MIN(J3:J9) -> 299.99
C11: Max: | D11: =MAX(D2:D7) -> 22.3 | I11: =MAX(I2:I7) -> 1244 | J11: =MAX(J2:J7) -> 3399
B12: Elimination | C12: Avg: | D12: =AVERAGE(D3:D9) -> 17.271429 | I12: =AVERAGE(I3:I9) -> 576.71429 | J12: =AVERAGE(J3:J9) -> 1541.2686
B13: Round 1:
B14: Selected (Already Own)

Sheet 6. Gimbals
A1: Gimbals
A2: Option | B2: Brand | C2: Model | D2: Supported Cameras | E2: Lipo Cells | F2: # of Axis | G2: Mass (grams) | H2: Price (US$) | I2: Link
A3: 8 | B3: Arris | C3: CM2000 V5.0 | D3: GoPro 3/3+ | E3: 3 | F3: 2 | G3: 240 | H3: 269 | I3: www.hobby-wing.com
B4: Arris | C4: CM3000 | D4: GoPro 3/3+ | E4: 3 | F4: 3 | G4: 252 | H4: 350 | I4: www.hobby-wing.com
B5: DJI | C5: H3-2D | D5: GoPro 3/3+ | E5: 3-6 | F5: 2 | G5: 157 | H5: 369 | I5: www.dji.com
A6: 1 | B6: DJI | C6: H3-3D | D6: GoPro 3/3+ | E6: 3-6 | F6: 3 | G6: 168 | H6: 399 | I6: www.dji.com
B7: DJI | C7: Z15 - 5D | D7: Canon 5D Mark III | E7: 4-12 | F7: 3 | G7: 1420 | H7: 2999 | I7: www.dji.com
B8: PhotoHigher | C8: AV130 | D8: GH2 | E8: ? | F8: 2 | G8: 410 | H8: 869 | I8: www.photohigher.co.nz
B9: PhotoHigher | C9: AV200 | D9: Canon 5D Mark II or 7D | E9: ? | F9: 2 | G9: 590 | H9: 975 | I9: www.photohigher.co.nz
A10: 1 | B10: Tarot | C10: T-2D | D10: GoPro 3/3+ | E10: 2-4 | F10: 2 | G10: 200 | H10: 139 | I10: www.hobby-wing.com
F11: MIN: | G11: =MIN(G3:G10) -> 157 | H11: =MIN(H3:H10) -> 139 | I11: =NOW() -> 41741.599
D12: Round 1: | F12: MAX: | G12: =MAX(G4:G11) -> 1420 | H12: =MAX(H4:H11) -> 2999
D13: Incompatible with GoPro | F13: AVG: | G13: =AVERAGE(G5:G12) -> 565.25 | H13: =AVERAGE(H5:H12) -> 1111
D15: Round 2:
D16: H3-3D is better
D17: Low Price
D19: Round 3:
D20: Trust DJI Gimbal over Arris
D22: Selected

Sheet 7. Motors
A1: Option | B1: Brand | C1: Line | D1: Model | E1: Lipo Cells | F1: KV (rpm/v) | G1: No Load Current (Amps) @10v | H1: Max Watts | I1: Max Current (Amps) | J1: Internal Resistance (ohm) | K1: Number of Poles | L1: Shaft Length (mm) | M1: Shaft Diameter (mm) | N1: Stator Diameter (mm) | O1: Body Length | P1: Mass (grams) | Q1: Recommended ESC (Amp Rating) | R1: Price (US$) | S1: Link | T1: Comments
A2: 37 | B2: Scorpion | C2: HKIII | D2: HKIII4035-330 | E2: 12 | F2: 330 | G2: 1.33 | H2: 3500 | I2: 60 | J2: 0.031 | K2: 10 | L2: 100 | M2: 5.98 | N2: 40 | O2: 68.1 | P2: 460 | Q2: 80 | R2: 199.99 | S2: www.scorpionsystem.com
B3: Scorpion | C3: HKIII | D3: HKIII4035-450 | E3: 12 | F3: 450 | G3: 1.85 | H3: 3300 | I3: 75 | J3: 0.02 | K3: 10 | L3: 100 | M3: 5.98 | N3: 40 | O3: 68.1 | P3: 460 | Q3: 100 | R3: 199.99 | S3: www.scorpionsystem.com
B4: Scorpion | C4: HKIII | D4: HKIII4035-500 | E4: 12 | F4: 500 | G4: 2.02 | H4: 4600 | I4: 84 | J4: 0.016 | K4: 10 | L4: 100 | M4: 5.98 | N4: 40 | O4: 68.1 | P4: 460 | Q4: 100 | R4: 199.99 | S4: www.scorpionsystem.com
B5: Scorpion | C5: HKIII | D5: HKIII4035-530 | E5: 12 | F5: 530 | G5: 2.15 | H5: 4400 | I5: 80 | J5: 0.015 | K5: 10 | L5: 100 | M5: 5.98 | N5: 40 | O5: 68.1 | P5: 460 | Q5: 100 | R5: 199.99 | S5: www.scorpionsystem.com
B6: Scorpion | C6: HKIII | D6: HKIII4035-560 | E6: 12 | F6: 560 | G6: 2.24 | H6: 5200 | I6: 100 | J6: 0.014 | K6: 10 | L6: 100 | M6: 5.98 | N6: 40 | O6: 68.1 | P6: 460 | Q6: 120 | R6: 199.99 | S6: www.scorpionsystem.com
A8: 1 | B8: Scorpion | C8: M-40 Series | D8: M4010-360 | E8: 3-6 | F8: 360 | G8: 0.34 | H8: 510 | I8: 23 | J8: 0.152 | K8: 14 | L8: 36.5 | M8: 3.98 | N8: 40 | O8: 32.17 | P8: 152 | Q8: 30 | R8: 99.99 | S8: www.scorpionsystem.com | U8: 14.8v 15inX5.5in (1125g @ 7.7 Amps) | V8: 22.2v 12inX5.5in (1225g @ 8.1 Amps)
A9: 2 | B9: Scorpion | C9: M-40 Series | D9: M4015-340 | E9: 3-8 | F9: 340 | G9: 0.47 | H9: 740 | I9: 25 | J9: 0.108 | K9: 14 | L9: 41 | M9: 3.98 | N9: 40 | O9: 37.17 | P9: 194 | Q9: 30 | R9: 109.99 | S9: www.scorpionsystem.com | U9: 14.8v 14inX5.5in (1000g @ 7.96 Amps) | V9: 22.2v 12inX5.5in (1250g @ 8.56 Amps)
B11: Scorpion | C11: SII | D11: SII4020-420 | E11: 6 | F11: 420 | G11: 0.91 | H11: 1500 | I11: 70 | J11: 0.034 | K11: 14 | L11: 78.4 | M11: 5.98 | N11: 40 | O11: 46.15 | P11: 288 | Q11: 80 | R11: 139.99 | S11: www.scorpionsystem.com
B12: Scorpion | C12: SII | D12: SII4020-540 | E12: 6 | F12: 540 | G12: 1.22 | H12: 1850 | I12: 85 | J12: 0.034 | K12: 14 | L12: 78.4 | M12: 5.98 | N12: 40 | O12: 46.15 | P12: 288 | Q12: 90 | R12: 139.99 | S12: www.scorpionsystem.com
B13: Scorpion | C13: SII | D13: SII4020-630 | E13: 5 | F13: 630 | G13: 1.54 | H13: 1500 | I13: 95 | J13: 0.034 | K13: 14 | L13: 78.4 | M13: 5.98 | N13: 40 | O13: 46.15 | P13: 288 | Q13: 100 | R13: 139.99 | S13: www.scorpionsystem.com
B15: Scorpion | C15: SII | D15: SII4025-330 | E15: 8 | F15: 330 | G15: 0.74 | H15: 2000 | I15: 75 | J15: 0.037 | K15: 14 | L15: 85 | M15: 5.98 | N15: 40 | O15: 54.1 | P15: 353 | Q15: 80 | R15: 149.99 | S15: www.scorpionsystem.com
B16: Scorpion | C16: SII | D16: SII4025-440 | E16: 7 | F16: 440 | G16: 1.1 | H16: 2000 | I16: 85 | J16: 0.025 | K16: 14 | L16: 85 | M16: 5.98 | N16: 40 | O16: 54.1 | P16: 353 | Q16: 90 | R16: 149.99 | S16: www.scorpionsystem.com
B17: Scorpion | C17: SII | D17: SII4025-520 | E17: 6 | F17: 520 | G17: 1.4 | H17: 2000 | I17: 100 | J17: 0.016 | K17: 14 | L17: 85 | M17: 5.98 | N17: 40 | O17: 54.1 | P17: 353 | Q17: 110 | R17: 149.99 | S17: www.scorpionsystem.com
B19: Scorpion | C19: SII | D19: SII4035-250 | E19: 12 | F19: 250 | G19: 0.69 | H19: 2700 | I19: 65 | J19: 0.037 | K19: 14 | L19: 95 | M19: 7.98 | N19: 40 | O19: 64.9 | P19: 450 | Q19: 70 | R19: 169.99 | S19: www.scorpionsystem.com
B20: Scorpion | C20: SII | D20: SII4035-330 | E20: 11 | F20: 330 | G20: 1.41 | H20: 2400 | I20: 65 | J20: 0.031 | K20: 10 | L20: 95 | M20: 7.98 | N20: 40 | O20: 64.9 | P20: 435 | Q20: 70 | R20: 169.99 | S20: www.scorpionsystem.com
B21: Scorpion | C21: SII | D21: SII4035-380 | E21: 11 | F21: 380 | G21: 1.52 | H21: 2600 | I21: 70 | J21: 0.025 | K21: 10 | L21: 95 | M21: 7.98 | N21: 40 | O21: 64.9 | P21: 435 | Q21: 80 | R21: 169.99 | S21: www.scorpionsystem.com
B22: Tiger | C22: Antigravity | D22: AG4014-330 | E22: 4-8 | F22: 330 | G22: 1.1 | H22: 750 | I22: 25 | J22: 0.085 | K22: 18 | L22: 14 | M22: 4 | N22: 44.8 | O22: 34.5 | P22: 149 | Q22: 30 | R22: 194.9 | S22: www.rctigermotor.com
A24: 3 | B24: Tiger | C24: Power | D24: U3-700 | E24: 3-4 | F24: 700 | G24: 0.5 | H24: 500 | I24: 25 | J24: 0.05 | K24: 14 | L24: ? | M24: 4 | N24: 41.8 | O24: 30.75 | P24: 97 | Q24: 30 | R24: 109.9 | S24: www.rctigermotor.com | U24: 14.8v 13inX4.4in (1120g @ 65%throttle)
A25: 4 | B25: Tiger | C25: Power | D25: U5-400 | E25: 3-8 | F25: 400 | G25: 0.3 | H25: 850 | I25: 30 | J25: 0.116 | K25: 14 | L25: ? | M25: 4 | N25: 42.5 | O25: 37.5 | P25: 156 | Q25: 35 | R25: 125.9 | S25: www.rctigermotor.com | T25: Too Powerful | U25: 22.2v 14inX4.8in (1200g @ 65%throttle)
B26: Tiger | C26: Power | D26: U7-420 | E26: 3-8 | F26: 420 | G26: 1.1 | H26: 1180 | I26: 40 | J26: 0.033 | K26: 14 | L26: ? | M26: 4 | N26: 60.7 | O26: 39.5 | P26: 255 | Q26: 40 | R26: 149.9 | S26: www.rctigermotor.com
B27: Tiger | C27: Power | D27: U7-490 | E27: 3-8 | F27: 490 | G27: 1.1 | H27: 1300 | I27: 44 | J27: 0.021 | K27: 14 | L27: ? | M27: 4 | N27: 60.7 | O27: 39.5 | P27: 258 | Q27: 44 | R27: 149.9 | S27: www.rctigermotor.com
B29: Tiger | C29: Professional | D29: MT4006-740 | E29: 3-4 | F29: 740 | G29: 0.5 | H29: 500 | I29: 27 | J29: 0.136 | K29: 24 | L29: 6 | M29: 4 | N29: 40 | O29: 24 | P29: 92 | Q29: 30 | R29: 82.9 | S29: www.rctigermotor.com | T29: not strong enough
B30: Tiger | C30: T-Motor | D30: MN3510-360 | E30: 3-6 | F30: 360 | G30: 0.4 | H30: 330 | I30: 15 | J30: 0.188 | K30: 14 | L30: 10 | M30: 4 | N30: 35 | O30: 28.5 | P30: 97 | Q30: 20 | R30: 79.9 | S30: www.rctigermotor.com
B31: Tiger | C31: T-Motor | D31: MN3510-630 | E31: 3-4 | F31: 630 | G31: 0.5 | H31: 495 | I31: 22 | J31: 0.065 | K31: 14 | L31: 10 | M31: 4 | N31: 35 | O31: 28.5 | P31: 97 | Q31: 25 | R31: 79.9 | S31: www.rctigermotor.com
A32: 5 | B32: Tiger | C32: T-Motor | D32: MN3510-700 | E32: 3-4 | F32: 700 | G32: 0.5 | H32: 555 | I32: 25 | J32: 0.05 | K32: 14 | L32: 10 | M32: 4 | N32: 35 | O32: 28.5 | P32: 97 | Q32: 25 | R32: 79.9 | S32: www.rctigermotor.com | U32: 14.8v 13inX4.4in (1120g @ 65%throttle)
B34: Tiger | C34: T-Motor | D34: MN3515-400 | E34: 4-8 | F34: 400 | G34: 0.3 | H34: 900 | I34: 30 | J34: 0.116 | K34: 14 | L34: 15 | M34: 4 | N34: 35 | O34: 34.5 | P34: 183 | Q34: 30 | R34: 96.9 | S34: www.rctigermotor.com
B35: Tiger | C35: T-Motor | D35: MN3520-400 | E35: 4-8 | F35: 400 | G35: 1.2 | H35: 1140 | I35: 38 | J35: 0.082 | K35: 14 | L35: 20 | M35: 4 | N35: 35 | O35: 42 | P35: 194 | Q35: 40 | R35: 109.9 | S35: www.rctigermotor.com
B37: Tiger | C37: T-Motor | D37: MN4010-370 | E37: 4-8 | F37: 370 | G37: 0.8 | H37: 450 | I37: 20 | J37: 0.098 | K37: 24 | L37: 10 | M37: 4 | N37: 40 | O37: 30.5 | P37: 112 | Q37: 20 | R37: 86.9 | S37: www.rctigermotor.com
A38: 6 | B38: Tiger | C38: T-Motor | D38: MN4010-475 | E38: 4-8 | F38: 475 | G38: 0.8 | H38: 540 | I38: 30 | J38: 0.098 | K38: 24 | L38: 10 | M38: 4 | N38: 40 | O38: 30.5 | P38: 110 | Q38: 30 | R38: 86.9 | S38: www.rctigermotor.com | U38: 14.8v 16inX5.4in (1060g @ 65%throttle) | V38: 22.2v 13inX4.4in (1070g @ 65%throttle)
A39: 7 | B39: Tiger | C39: T-Motor | D39: MN4010-580 | E39: 4-8 | F39: 580 | G39: 1.3 | H39: 575 | I39: 31 | J39: 0.042 | K39: 24 | L39: 10 | M39: 4 | N39: 40 | O39: 30.5 | P39: 112 | Q39: 40 | R39: 86.9 | S39: www.rctigermotor.com | U39: 14.8v 14inX4.8in (1000g @ 65%throttle) | V39: 14.8v 15inX5in (1190g @ 65%throttle)
A41: 8 | B41: Tiger | C41: T-Motor | D41: MN4012-340 | E41: 4-8 | F41: 340 | G41: 0.9 | H41: 660 | I41: 22 | J41: 0.133 | K41: 24 | L41: 12 | M41: 4 | N41: 40 | O41: 32.5 | P41: 131 | Q41: 30 | R41: 92.9 | S41: www.rctigermotor.com | U41: 22.2v 15inX5in (1110g @ 65%throttle)
A42: 9 | B42: Tiger | C42: T-Motor | D42: MN4012-400 | E42: 4-8 | F42: 400 | G42: 1 | H42: 750 | I42: 25 | J42: 0.075 | K42: 24 | L42: 12 | M42: 4 | N42: 40 | O42: 32.5 | P42: 128 | Q42: 30 | R42: 92.9 | S42: www.rctigermotor.com | U42: 22.2v 14inX4.8in (1150g @ 65%throttle)
B43: Tiger | C43: T-Motor | D43: MN4012-480 | E43: 4-8 | F43: 480 | G43: 1.3 | H43: 870 | I43: 29 | J43: 0.057 | K43: 24 | L43: 12 | M43: 4 | N43: 40 | O43: 32.5 | P43: 134 | Q43: 30 | R43: 92.9 | S43: www.rctigermotor.com
A45: 10 | B45: Tiger | C45: T-Motor | D45: MN4014-330 | E45: 4-8 | F45: 330 | G45: 1.1 | H45: 750 | I45: 25 | J45: 0.085 | K45: 24 | L45: 14 | M45: 4 | N45: 40 | O45: 34.5 | P45: 149 | Q45: 25 | R45: 96.9 | S45: www.rctigermotor.com | U45: 22.2v 15inX5in (1150g @ 65%throttle)
B46: Tiger | C46: T-Motor | D46: MN4014-400 | E46: 4-8 | F46: 400 | G46: 1.3 | H46: 900 | I46: 30 | J46: 0.067 | K46: 24 | L46: 14 | M46: 4 | N46: 40 | O46: 34.5 | P46: 150 | Q46: 30 | R46: 96.9 | S46: www.rctigermotor.com
B48: Tiger | C48: T-Motor | D48: MN4120-400 | E48: 4-8 | F48: 400 | G48: 1.12 | H48: 1050 | I48: 47 | J48: 0.03 | K48: 14 | L48: 20 | M48: 4 | N48: 41 | O48: 42 | P48: 253 | Q48: 50 | R48: 119.9 | S48: www.rctigermotor.com
A49: 10 | B49: Tiger | C49: T-Motor | D49: MN4120-465 | E49: 4-8 | F49: 465 | G49: 1.4 | H49: 1200 | I49: 50 | J49: 0.024 | K49: 14 | L49: 20 | M49: 4 | N49: 41 | O49: 42 | P49: 253 | Q49: 50 | R49: 119.9 | S49: www.rctigermotor.com
E50: Min: | F50: =MIN(F48:F49,F45:F46,F41:F43,F37:F39,F34:F35,F25:F27,F11:F13,F8:F9) -> 330 | G50: =MIN(G48:G49,G45:G46,G41:G43,G37:G39,G34:G35,G25:G27,G11:G13,G8:G9) -> 0.3 | H50: =MIN(H48:H49,H45:H46,H41:H43,H37:H39,H34:H35,H25:H27,H11:H13,H8:H9) -> 450 | I50: =MIN(I48:I49,I45:I46,I41:I43,I37:I39,I34:I35,I25:I27,I11:I13,I8:I9) -> 20 | J50: =MIN(J48:J49,J45:J46,J41:J43,J37:J39,J34:J35,J25:J27,J11:J13,J8:J9) -> 0.021 | K50: =MIN(K48:K49,K45:K46,K41:K43,K37:K39,K34:K35,K25:K27,K11:K13,K8:K9) -> 14 | L50: =MIN(L48:L49,L45:L46,L41:L43,L37:L39,L34:L35,L25:L27,L11:L13,L8:L9) -> 10 | M50: =MIN(M48:M49,M45:M46,M41:M43,M37:M39,M34:M35,M25:M27,M11:M13,M8:M9) -> 3.98 | ... R50: =MIN(R48:R49,R45:R46,R41:R43,R37:R39,R34:R35,R25:R27,R11:R13,R8:R9) -> 86.9 | S50: =NOW() -> 41741.599
E51: Max: | F51: =MAX(F48:F49,F45:F46,F41:F43,F37:F39,F34:F35,F25:F27,F11:F13,F8:F9) -> 630 | G51: =MAX(G48:G49,G45:G46,G41:G43,G37:G39,G34:G35,G25:G27,G11:G13,G8:G9) -> 1.54 | H51: =MAX(H48:H49,H45:H46,H41:H43,H37:H39,H34:H35,H25:H27,H11:H13,H8:H9) -> 1850 | I51: =MAX(I48:I49,I45:I46,I41:I43,I37:I39,I34:I35,I25:I27,I11:I13,I8:I9) -> 95 | J51: =MAX(J48:J49,J45:J46,J41:J43,J37:J39,J34:J35,J25:J27,J11:J13,J8:J9) -> 0.152 | K51: =MAX(K48:K49,K45:K46,K41:K43,K37:K39,K34:K35,K25:K27,K11:K13,K8:K9) -> 24 | L51: =MAX(L48:L49,L45:L46,L41:L43,L37:L39,L34:L35,L25:L27,L11:L13,L8:L9) -> 78.4 | M51: =MAX(M48:M49,M45:M46,M41:M43,M37:M39,M34:M35,M25:M27,M11:M13,M8:M9) -> 5.98 | ... R51: =MAX(R48:R49,R45:R46,R41:R43,R37:R39,R34:R35,R25:R27,R11:R13,R8:R9) -> 149.9
...

Sheet 8. ESCs
A1: Electronic Speed Controllers (ESC)
A2: Option | B2: Brand | C2: MODEL | D2: method | E2: Continuous Current (A) | F2: Burst Current (A) | G2: Lipo Cells | H2: MASS (g) | I2: Simon K Firmware? | J2: PRICE | K2: Link
A3: 1 | B3: Hobbywing | C3: FlyFun 30 | D3: BEC | E3: 30 | F3: 40 | G3: 2-4 | H3: 25 | J3: 19.99 | K3: http://www.hobby-wing.com
A4: 2 | B4: Hobbywing | C4: FlyFun 40 | D4: BEC | E4: 40 | F4: 60 | G4: 2-6 | H4: 35 | J4: 28.5 | K4: http://www.hobby-wing.com
A5: 3 | B5: Hobbywing | C5: Platinum 30 | D5: OPTO | E5: 30 | F5: 45 | G5: 2-6 | H5: 31.6 | J5: 26 | K5: http://www.hobby-wing.com/hobby-wing-platinum-30a-pro.html
A7: 4 | B7: Maytech | C7: MT 30 | D7: OPTO | E7: 30 | F7: 40 | G7: 2-4 | H7: 27 | J7: 30 | K7: http://www.rc-drones.com/Maytech-MT30A-ESC.php
A8: 5 | B8: Maytech | C8: MT 35 | D8: OPTO | E8: 35 | F8: 50 | G8: 2-4 | H8: 27 | J8: 30 | K8: http://www.rc-drones.com/Maytech-MT35A-esc.php
A9: 6 | B9: Maytech | C9: MT 40 | D9: OPTO | E9: 40 | F9: 60 | G9: 2-6 | H9: 35 | J9: 37 | K9: http://www.rc-drones.com/rcd-mt40a-opto-v1-esc.php
B10: Maytech | C10: MT 60 | D10: OPTO | E10: 60 | F10: 80 | G10: 2-6 | H10: 51 | J10: 60 | K10: http://www.rc-drones.com/rcd-mt60a-opto-v1-esc.php
A12: 7 | B12: T-Motor | C12: T 30 | D12: BEC | E12: 30 | F12: 40 | G12: 2-4 | H12: 25 | J12: 28.99 | K12: http://www.rctigermotor.com/html/2013/esc_0916/83.html
A13: 8 | B13: T-Motor | C13: T 30 Pro | D13: NO-BEC | E13: 30 | F13: 40 | G13: 2-6 | H13: 31 | J13: 49.99 | K13: http://www.rctigermotor.com/html/2013/esc_0916/87.html
A14: 9 | B14: T-Motor | C14: T 40 | D14: BEC | E14: 40 | F14: 60 | G14: 2-6 | H14: 35 | J14: 45.99 | K14: http://www.rctigermotor.com/html/2013/esc_0916/84.html
A15: 10 | B15: T-Motor | C15: T 40 Pro | D15: ? | E15: 40 | F15: 60 | G15: 2-6 | H15: 29 | J15: 55.99 | K15: http://www.rctigermotor.com/html/2013/esc_0916/88.html
B16: T-Motor | C16: T 60 | D16: BEC | E16: 60 | F16: 80 | G16: 2-6 | H16: 60 | J16: 59.99 | K16: http://www.rctigermotor.com/html/2013/esc_0916/85.html
B18: Turnigy | C18: Multistar 20 | D18: BEC Switching | E18: 20 | F18: ? | G18: 2-4 | H18: 25 | J18: 10.55 | K18: http://www.hobbyking.com/hobbyking/store/__25364__Turnigy_Multistar_20_Amp_Multi_rotor_Brushless_ESC_2_4S.html
B19: Turnigy | C19: Multistar 30 | D19: OPTO | E19: 30 | F19: ? | G19: 2-4 | H19: 32 | J19: 11.29 | K19: http://www.hobbyking.com/hobbyking/store/__27776__Turnigy_Multistar_30_Amp_Multi_rotor_Brushless_ESC_2_4S_OPTO_.html
B20: Turnigy | C20: Multistar 45 | D20: OPTO | E20: 45 | F20: ? | G20: 2-6 | H20: 63 | J20: 19.46 | K20: http://www.hobbyking.com/hobbyking/store/__27777__Turnigy_Multistar_45_Amp_Multi_rotor_Brushless_ESC_2_6S_OPTO_.html
B21: Turnigy | C21: Multistar 60 | D21: OPTO | E21: 60 | F21: ? | G21: 2-6 | H21: 62 | J21: 22.12 | K21: http://www.hobbyking.com/hobbyking/store/__45503__Turnigy_Multistar_60_Amp_Multi_rotor_Brushless_ESC_2_6S_OPTO_.html
B23: Turnigy | C23: Plush 25 | D23: BEC Linear | E23: 25 | F23: 35 | G23: 2-4 | H23: 22 | J23: 13.44 | K23: http://www.hobbyking.com/hobbyking/store/uh_viewitem.asp?idproduct=2163&aff=586251
B24: Turnigy | C24: Plush 30 | D24: BEC Linear | E24: 30 | F24: 40 | G24: 2-4 | H24: 25 | J24: 13.13 | K24: http://www.hobbyking.com/hobbyking/store/uh_viewitem.asp?idproduct=2164&aff=586251
B25: Turnigy | C25: Plush 40 | D25: BEC Linear | E25: 40 | F25: 55 | G25: 2-6 | H25: 33 | J25: 21.99 | K25: http://www.hobbyking.com/hobbyking/store/uh_viewitem.asp?idproduct=2165&aff=586251
B26: Turnigy | C26: Plush 60 | D26: BEC Switching | E26: 60 | F26: 80 | G26: 2-6 | H26: 60 | J26: 34.88 | K26: http://www.hobbyking.com/hobbyking/store/uh_viewitem.asp?idproduct=2166&aff=586251
B28: Turnigy | C28: Super Brain 45 | D28: BEC Linear | E28: 45 | F28: 65 | G28: 2-6 | H28: 40 | J28: 39.19 | K28: http://www.hobbyking.com/hobbyking/store/__24889__Turnigy_Super_Brain_45A_6s_Brushless_ESC.html
B29: Turnigy | C29: Super Brain 60 | D29: BEC Switching | E29: 60 | F29: 70 | G29: 2-6 | H29: 50 | J29: 49.99 | K29: http://www.hobbyking.com/hobbyking/store/__10942__Turnigy_Super_Brain_60A_Brushless_ESC.html
A30: 10 | B30: Turnigy | C30: Super Brain 80 | D30: BEC Switching | E30: 80 | F30: 90 | G30: 2-6 | H30: 52 | J30: 69.99 | K30: http://www.hobbyking.com/hobbyking/store/__10943__Turnigy_Super_Brain_80A_Brushless_ESC.html
C32: Round 1:
C33: Skipped
C35: Round 2:
C36: All Motors < 50A
C38: Round 3:
C39: Not Turnigy

Sheet 9. Batteries
A1: Batteries
A2: Option | B2: Brand | C2: Model | D2: Lipo Cells | E2: Voltage | F2: mAh | G2: Max Continuous Current (Amps) | H2: Peak Current | I2: Length (mm) | J2: Width (mm) | K2: Height (mm) | L2: Mass (grams) | M2: Price (US$) | N2: $/mAh | O2: mAh/g | P2: Link
A3: 1 | B3: ADC | C3: 10,000mAh 6S 25C | D3: 6 | E3: 22.2 | F3: 10000 | G3: 40 | H3: ? | I3: 165 | J3: 62 | K3: 55 | L3: 1368 | M3: 279 | N3: =M3/F3 -> 0.0279 | O3: =F3/L3 -> 7.3099415 | P3: http://www.hobby-wing.com/roc-6s-10000mah-25c-polymer-lithium-lipo-battery.html
B4: ADC | C4: 5000mAh 6S 40C | D4: 6 | E4: 22.2 | F4: 5000 | G4: 40 | H4: ? | I4: 145 | J4: 50 | K4: 50 | L4: 790 | M4: 189 | N4: =M4/F4 -> 0.0378 | O4: =F4/L4 -> 6.3291139 | P4: http://www.hobby-wing.com/roc-6s-22v-5000mah-40c-battery.html
A5: 2 | B5: E-flite | C5: 5000mAh 5S 30C | D5: 5 | E5: 18.5 | F5: 5000 | G5: 30 | H5: ? | I5: 164 | J5: 43.2 | K5: 45.7 | L5: 672 | M5: 149.99 | N5: =M5/F5 -> 0.029998 | O5: =F5/L5 -> 7.4404762 | P5: http://www.horizonhobby.com/products/5000mah-5s-18-5v-30c-lipo-10awg-ec5-EFLB50005S30
B6: E-flite | C6: 5000mAh 6S 30C | D6: 6 | E6: 22.2 | F6: 5000 | G6: 30 | H6: ? | I6: 164 | J6: 54.6 | K6: 43.2 | L6: 808 | M6: 179.99 | N6: =M6/F6 -> 0.035998 | O6: =F6/L6 -> 6.1881188 | P6: http://www.horizonhobby.com/products/5000mah-6s-22-2v-30c-lipo-10awg-ec5-EFLB50006S30#t2
B7: E-flite | C7: 5000mAh 6S 50C | D7: 6 | E7: 22.2 | F7: 5000 | G7: 50 | H7: ? | I7: 134 | J7: 64 | K7: 45 | L7: 834 | M7: 239.99 | N7: =M7/F7 -> 0.047998 | O7: =F7/L7 -> 5.9952038 | P7: http://www.horizonhobby.com/products/5000mah-6s-22-2v-50c-lipo-10awg-ec5-EFLB50006S50#t2
A8: 3 | B8: Hyperion | C8: G3 4S 5000 35C | D8: 4 | E8: 14.8 | F8: 5000 | G8: 35 | H8: 65 | I8: 158.8 | J8: 45 | K8: 37.6 | L8: 545 | M8: 120 | N8: =M8/F8 -> 0.024 | O8: =F8/L8 -> 9.1743119 | P8: http://rc-drones.com/hyp-G3-5000-4s.php
A9: 4 | B9: Hyperion | C9: G3 4S 5400 35C | D9: 4 | E9: 14.8 | F9: 5400 | G9: 35 | H9: 65 | I9: 158.5 | J9: 46.8 | K9: 40.2 | L9: 594 | M9: 127.99 | N9: =M9/F9 -> 0.023701852 | O9: =F9/L9 -> 9.0909091 | P9: http://rc-drones.com/hyp-g3-vx5400-4s.php
B10: Hyperion | C10: G3 6S 5000 35C | D10: 6 | E10: 22.2 | F10: 5000 | G10: 35 | H10: 65 | I10: 158.5 | J10: 45 | K10: 55.8 | L10: 849 | M10: 163 | N10: =M10/F10 -> 0.0326 | O10: =F10/L10 -> 5.8892815 | P10: http://www.rc-drones.com/hyp-G3-VX-5000mAh-6S-35C.php
B11: Hyperion | C11: G3 6S 5400 35C | D11: 6 | E11: 22.2 | F11: 5400 | G11: 35 | H11: 65 | I11: 158.5 | J11: 46.8 | K11: 60.5 | L11: 920 | M11: 189 | N11: =M11/F11 -> 0.035 | O11: =F11/L11 -> 5.8695652 | P11: http://www.rc-drones.com/hyp-g36s-5400.php
B12: ThunderPower | C12: 5000mAh 6S 70C | D12: 6 | E12: 22.2 | F12: 5000 | G12: 70 | H12: 140 | I12: 156 | J12: 46 | K12: 49 | L12: 796 | M12: 246.99 | N12: =M12/F12 -> 0.049398 | O12: =F12/L12 -> 6.281407 | P12: http://www.horizonhobby.com/products/5000mah-6s-22-2v-g8-pro-force-70c-lipo-THP50006SPF70#t2
A13: 5 | B13: Turnigy | C13: A-SPEC 5000mAh 4S 65C | D13: 4 | E13: 14.8 | F13: 5000 | G13: 65 | H13: 130 | I13: 156 | J13: 46 | K13: 35 | L13: 537 | M13: 90.66 | N13: =M13/F13 -> 0.018132 | O13: =F13/L13 -> 9.310987 | P13: http://www.hobbyking.com/hobbyking/store/__45143__Turnigy_nano_tech_A_SPEC_G2_5000mah_4S_65_130C_Lipo_Pack.html
B14: Turnigy | C14: A-SPEC 5000mAh 6S 65C | D14: 6 | E14: 22.2 | F14: 5000 | G14: 65 | H14: 130 | I14: 156 | J14: 46 | K14: 51 | L14: 786 | M14: 148.05 | N14: =M14/F14 -> 0.02961 | O14: =F14/L14 -> 6.3613232 | P14: http://www.hobbyking.com/hobbyking/store/__45145__Turnigy_nano_tech_A_SPEC_G2_5000mah_6S_65_130C_Lipo_Pack.html
B15: Turnigy | C15: A-SPEC 5000mAh 6S 65C | D15: 6 | E15: 22.2 | F15: 5000 | G15: 65 | H15: 130 | I15: 153 | J15: 54 | K15: 49 | L15: 840 | M15: 129.99 | N15: =M15/F15 -> 0.025998 | O15: =F15/L15 -> 5.952381 | P15: http://www.hobbyking.com/hobbyking/store/__45145__Turnigy_nano_tech_A_SPEC_G2_5000mah_6S_65_130C_Lipo_Pack.html
B16: Turnigy | C16: A-SPEC G2 5000mAh 6S 65C | D16: 6 | E16: 22.2 | F16: 5000 | G16: 65 | H16: 130 | I16: 156 | J16: 51 | K16: 46 | L16: 786 | M16: 148.05 | N16: =M16/F16 -> 0.02961 | O16: =F16/L16 -> 6.3613232 | P16: http://www.hobbyking.com/hobbyking/store/__45145__Turnigy_nano_tech_A_SPEC_G2_5000mah_6S_65_130C_Lipo_Pack.html
A17: 6 | B17: Turnigy | C17: nano-tech 5000mAh 4S 65C | D17: 4 | E17: 14.8 | F17: 5000 | G17: 65 | H17: 130 | I17: 153 | J17: 49 | K17: 37 | L17: 576 | M17: 76.59 | N17: =M17/F17 -> 0.015318 | O17: =F17/L17 -> 8.6805556 | P17: http://www.hobbyking.com
A18: 7 | B18: Turnigy | C18: nano-tech 5000mAh 5S 65C | D18: 5 | E18: 18.5 | F18: 5000 | G18: 65 | H18: 130 | I18: 154 | J18: 46 | K18: 49 | L18: 712 | M18: 88.85 | N18: =M18/F18 -> 0.01777 | O18: =F18/L18 -> 7.0224719 | P18: http://www.hobbyking.com/hobbyking/store/__19155__Turnigy_nano_tech_5000mah_5S_65_130C_Lipo_Pack.html
A19: 7 | B19: Turnigy | C19: nano-tech 5000mAh 6S 65C | D19: 6 | E19: 22.2 | F19: 5000 | G19: 65 | H19: 130 | I19: 153 | J19: 49 | K19: 55 | L19: 844 | M19: 116.7 | N19: =M19/F19 -> 0.02334 | O19: =F19/L19 -> 5.9241706 | P19: http://www.hobbyking.com/hobbyking/store/__19156__Turnigy_nano_tech_5000mah_6S_65_130C_Lipo_Pack.html
C20: Min: | D20: =MIN(D3:D19) -> 4 | E20: =MIN(E3:E19) -> 14.8 | F20: =MIN(F3:F19) -> 5000 | G20: =MIN(G3:G19) -> 30 | H20: =MIN(H3:H19) -> 65 | I20: =MIN(I3:I19) -> 134 | J20: =MIN(J3:J19) -> 43.2 | K20: =MIN(K3:K19) -> 35 | L20: =MIN(L3:L19) -> 537 | M20: =AVERAGE(M3:M19) -> 157.87294
C21: Max: | D21: =MAX(D3:D19) -> 6 | E21: =MAX(E3:E19) -> 22.2 | F21: =MAX(F3:F19) -> 10000 | G21: =MAX(G3:G19) -> 70 | H21: =MAX(H3:H19) -> 140 | I21: =MAX(I3:I19) -> 165 | J21: =MAX(J3:J19) -> 64 | K21: =MAX(K3:K19) -> 60.5 | ... M21: =MAX(M3:M19) -> 279
C22: Avg: | D22: =AVERAGE(D3:D19) -> 5.4117647 | E22: =AVERAGE(E3:E19) -> 20.023529 | F22: =AVERAGE(F3:F19) -> 5341.1765 | G22: =AVERAGE(G3:G19) -> 50.294118 | H22: =AVERAGE(H3:H19) -> 109.16667 | I22: =AVERAGE(I3:I19) -> 155.48824 | J22: =AVERAGE(J3:J19) -> 49.670588 | K22: =AVERAGE(K3:K19) -> 47.294118 | ... M22: =AVERAGE(M3:M19) -> 157.87294
C23: Round 1:
C24: Skipped
C26: Round 2:
C27: > $0.03 per mAh
C29: Round 3:
C30: < 7 mAh/g

Sheet 10. Propellers
A1: Propellers
A2: Option | B2: Brand | C2: Line | D2: Model | E2: Folding? | F2: Diameter (in) | G2: Pitch (in/in) | H2: Material | I2: Mass (grams) | J2: QTY | K2: Price (US$) | L2: $/Prop | M2: Link
B3: Graupner | C3: E-Prop | D3: 11x5 | E3: N | F3: 11 | G3: 5 | H3: CF | I3: 0 | J3: 1 | K3: 12 | L3: =K3/J3 -> 12 | M3: http://www.rc-drones.com/Graupner-Eprop-11right.php
B4: Maytech | C4: MTCP1155T | D4: 11x5.5 | E4: N | F4: 11 | G4: 5.5 | H4: CF | I4: 0 | J4: 2 | K4: 26 | L4: =K4/J4 -> 13 | M4: http://www.rc-drones.com/Maytech-MTCP1155T-11prop.php
B5: APC | C5: APC Prop | D5: 12x4.5 | E5: N | F5: 12 | G5: 4.5 | H5: P | I5: 0 | J5: 1 | K5: 4 | L5: =K5/J5 -> 4 | M5: http://www.rc-drones.com/APC-12x4-5-Left-Propeller.php
A6: 1 | B6: Maytech | C6: MTCP1255T | D6: 12x5.5 | E6: N | F6: 12 | G6: 5.5 | H6: CF | I6: 0 | J6: 2 | K6: 30 | L6: =K6/J6 -> 15 | M6: http://www.rc-drones.com/Maytech-MTCP1255T-12prop.php
A7: 2 | B7: Sigma | C7: CF Prop | D7: 12x3.8 | E7: N | F7: 12 | G7: 3.8 | H7: CF | I7: 15.4 | J7: 2 | K7: 20 | L7: =K7/J7 -> 10 | M7: http://www.hobby-wing.com/sigma-1238-carbon-fiber-propeller.html
A8: 3 | B8: Tarot | C8: HE CF Prop | D8: 12x5.5 | E8: N | F8: 12 | G8: 5.5 | H8: CF | I8: 11.2 | J8: 2 | K8: 15 | L8: =K8/J8 -> 7.5 | M8: http://www.hobby-wing.com/tarot--tl2828-1255-propeller.html
A9: 4 | B9: Maytech | C9: MTCP1355T | D9: 13x5.5 | E9: N | F9: 13 | G9: 5.5 | H9: CF | I9: 0 | J9: 2 | K9: 35 | L9: =K9/J9 -> 17.5 | M9: http://www.rc-drones.com/Maytech-MTCP1355T-13prop.php
A10: 5 | B10: Sigma | C10: CF Prop | D10: 13x4.0 | E10: N | F10: 13 | G10: 4 | H10: CF | I10: 0 | J10: 2 | K10: 20 | L10: =K10/J10 -> 10 | M10: http://www.hobby-wing.com
A11: 6 | B11: Tarot | C11: HE CF Prop | D11: 13x5.5 | E11: N | F11: 13 | G11: 5.5 | H11: CF | I11: 14 | J11: 2 | K11: 18 | L11: =K11/J11 -> 9 | M11: http://www.hobby-wing.com/tarot-1355-propeller-tl2829.html
A12: 7 | B12: GemFan | C12: Hobby | D12: 14x7 | E12: N | F12: 14 | G12: 7 | H12: CF | I12: 0 | J12: 2 | K12: 36 | L12: =K12/J12 -> 18 | M12: http://www.rc-drones.com/gemfan-137.php
A13: 8 | B13: Graupner | C13: E-Prop | D13: 14x8 | E13: N | F13: 14 | G13: 8 | H13: CF | I13: 0 | J13: 1 | K13: 18 | L13: =K13/J13 -> 18 | M13: http://www.rc-drones.com/Graupner-Eprop-14Left.php
A14: 9 | B14: Maytech | C14: MTCP1455T | D14: 14x5.5 | E14: N | F14: 14 | G14: 5.5 | H14: CF | I14: 0 | J14: 2 | K14: 40 | L14: =K14/J14 -> 20 | M14: http://www.rc-drones.com/Maytech-MTCP1455T-14prop.php
B15: DJI | C15: DJI Folding | D15: 15x5.2 | E15: Y | F15: 15 | G15: 5.2 | H15: ? | I15: 13 | J15: 2 | K15: 69 | L15: =K15/J15 -> 34.5 | M15: http://www.hobby-wing.com/1552-folding-cf-propeller.html
A16: 10 | B16: DJI | C16: DJI Folding | D16: 15x5.2 | E16: Y | F16: 15 | G16: 5.2 | H16: PC | I16: 13 | J16: 2 | K16: 45 | L16: =K16/J16 -> 22.5 | M16: http://www.hobby-wing.com/dji-1552-folding-propeller.html
A17: 11 | B17: GemFan | C17: DJI S800 Style | D17: 15x5.5 | E17: N | F17: 15 | G17: 5.5 | H17: CF | I17: 16.4 | J17: 2 | K17: 40 | L17: =K17/J17 -> 20 | M17: http://www.rc-drones.com/gemfan-S800-Prop.php
A18: 12 | B18: GemFan | C18: Scoop Style | D18: 15x7.5 | E18: N | F18: 15 | G18: 7.5 | H18: CF | I18: 12.5 | J18: 2 | K18: 40 | L18: =K18/J18 -> 20 | M18: http://www.rc-drones.com/gemfan-djiscoop-15Prop.php
A19: 13 | B19: Gemfan | C19: T-Motor | D19: 15x5.5 | E19: N | F19: 15 | G19: 5.5 | H19: CF | I19: 0 | J19: 2 | K19: 40 | L19: =K19/J19 -> 20 | M19: http://www.rc-drones.com/gemfan-rcd15x5.php
A20: 14 | B20: High Performance | C20: CF Prop | D20: 15x5.5 | E20: N | F20: 15 | G20: 5.5 | H20: CF | I20: 0 | J20: 2 | K20: 35 | L20: =K20/J20 -> 17.5 | M20: http://www.hobby-wing.com/t-motor-1555-cf-propeller.html
B21: RC Tiger | C21: T-Motor | D21: 15x5 | E21: N | F21: 15 | G21: 5 | H21: CF | I21: 0 | J21: 2 | K21: 75 | L21: =K21/J21 -> 37.5 | M21: http://www.rc-drones.com/RcTiger15CF-props.php
A22: 15 | B22: Sigma | C22: CF Prop | D22: 15x4.0 | E22: N | F22: 15 | G22: 4 | H22: CF | I22: 17 | J22: 2 | K22: 29.99 | L22: =K22/J22 -> 14.995 | M22: http://www.hobby-wing.com/p1540c-carbon-fiber-propeller.html
A23: 16 | B23: Sigma | C23: Multicopter | D23: 15x5.5 | E23: N | F23: 15 | G23: 5.5 | H23: CF | I23: 0 | J23: 2 | K23: 35 | L23: =K23/J23 -> 17.5 | M23: http://www.hobby-wing.com/1550-carbon-fiber-propeller.html
A24: 17 | B24: Tarot | C24: HE CF Prop | D24: 15x5.5 | E24: N | F24: 15 | G24: 5.5 | H24: CF | I24: 18.2 | J24: 2 | K24: 25 | L24: =K24/J24 -> 12.5 | M24: http://www.hobby-wing.com/tarot-1555-propeller-tl2812.html
A25: 18 | B25: GemFan | C25: Paddle Style | D25: 15.5x5.5 | E25: N | F25: 15.5 | G25: 5.5 | H25: CF | I25: 20 | J25: 2 | K25: 40 | L25: =K25/J25 -> 20 | M25: http://www.rc-drones.com/gemfan-paddlestyle-15Prop.php
A26: 19 | B26: High Performance | C26: CF Prop | D26: 16x5.5 | E26: N | F26: 16 | G26: 5.5 | H26: CF | I26: 0 | J26: 2 | K26: 38 | L26: =K26/J26 -> 19 | M26: http://www.hobby-wing.com/t-motor-1655-cf-propeller.html
A27: 20 | B27: Tarot | C27: HE CF Prop | D27: 16x5.5 | E27: N | F27: 16 | G27: 5.5 | H27: CF | I27: 23 | J27: 2 | K27: 28 | L27: =K27/J27 -> 14 | M27: http://www.hobby-wing.com/tarot-1655-propeller-tl2835.html
B28: Sigma | C28: Multicopter | D28: 17x5.5 | E28: N | F28: 17 | G28: 5.5 | H28: CF | I28: 0 | J28: 2 | K28: 45 | L28: =K28/J28 -> 22.5 | M28: http://www.hobby-wing.com/1755-carbon-fiber-propeller.html
B29: Tarot | C29: HE CF Prop | D29: 17x5.5 | E29: N | F29: 17 | G29: 5.5 | H29: CF | I29: 0 | J29: 2 | K29: 35 | L29: =K29/J29 -> 17.5 | M29: http://www.hobby-wing.com/tl2815.html
A30: 20 | B30: GemFan | C30: CF Folding Prop | D30: ? | E30: Y | F30: ? | G30: ? | H30: CF | I30: 0 | J30: 1 | K30: 20 | L30: =K30/J30 -> 20 | M30: http://www.rc-drones.com/gemfamFoldingCW-S800props.php
B32: Round 1:
B33: Skipped
B35: Round 2:
B36: 12 <= Prop <= 16
B37: High Price
B38: Weak Material
B40: Round 3:

Sheet 11. Accessories
A1: Accessories
A2: Options for GPS Accessories | B2: Brand | C2: Line | D2: Model | E2: Battery Life Span | F2: Smartphone/Tablet/Computer Trackable? | G2: Height (mm) | H2: Width (mm) | I2: Thickness (mm) | J2: Waterproof? | K2: Mass (grams) | L2: Line Power | M2: Power Source | N2: Service Plan Required? | O2: Subscription Price | P2: Duration | Q2: Product Price | R2: Total Price with 1 year subscription (USD) | S2: Link
A3: 1 | B3: Spot | C3: GPS Tracker | D3: Trace | E3: 1 year | F3: Y | G3: 68.3 | H3: 51.3 | I3: 21.4 | J3: 30 Min @ 1m | K3: 88 | L3: 5v USB | M3: (4) AAA | N3: Y | O3: 99.99 | P3: per year | Q3: 99.85 | R3: =O3+Q3 -> 199.84 | S3: www.findmespot.com
A4: 2 | B4: BrickHouse Security | C4: GPS Tracker | D4: TrackPort | G4: 55 | H4: 50 | I4: 25 | K4: 80 | M4: OBD-II port | O4: 29.95 | P4: per month | Q4: 99.95 | R4: =O4*12+Q4 -> 459.35
S5: =NOW() -> 41741.599
B6: Round 1:
B7: Selected
D33: ='11. Accessories'!A6d -> #NAME?

Sheet Scorecard
A1: Elective BOM Option | B1: Motor Model | C1: Hover Flight Time (minutes) | D1: Hover Score | E1: Weight (grams) | F1: Weight Score | G1: Additional Payload (grams) | H1: Additional Payload Score | I1: Throttle at Hover (%) | J1: Throttle At Hover Score | K1: Recommended Props | L1: Prop Score | M1: Total Score (higher is better) | N1: Weighted Total Score Option 1 | O1: Weighted Total Score Option 2 | P1: ecalc Link | S1: Rank Worst to Best | T1: No Weight | U1: Weight Option 1 | V1: Weight Option 2
A2: 2 | B2: 3525-650 | C2: 15.9 | D2: 4 | E2: 1798 | F2: 2 | G2: 855 | H2: 1 | I2: 53 | J2: 1 | K2: 10x4.7 - 11x4.7 | L2: 3 | M2: =D2+F2+H2+J2+L2 -> 11 | N2: =D2*5+F2*3+H2*4+J2+L2*2 -> 37 | O2: =D2*3+F2*2+H2*2.5+J2+L2 -> 22.5 | P2: Link | S2: 4 | T2: 3525-650 | U2: 3530-1150 | V2: 3525-650
A3: 1 | B3: 3530-1150 | C3: 13.2 | D3: 1 | E3: 1756 | F3: 3 | G3: 2165 | H3: 4 | I3: 31 | J3: 4 | K3: 8x5 - 11x4.7 | L3: 1 | M3: =D3+F3+H3+J3+L3 -> 13 | N3: =D3*5+F3*3+H3*4+J3+L3*2 -> 36 | O3: =D3*3+F3*2+H3*2.5+J3+L3 -> 24 | P3: Link | S3: 3 | T3: 3530-1150 | U3: 3525-650 | V3: 3530-1150
A4: 3 | B4: 3525-850 | C4: 13.4 | D4: 2 | E4: 1664 | F4: 4 | G4: 880 | H4: 2 | I4: 51 | J4: 2 | K4: 10x4.7 - 11x4.7 | L4: 3 | M4: =D4+F4+H4+J4+L4 -> 13 | N4: =D4*5+F4*3+H4*4+J4+L4*2 -> 38 | O4: =D4*3+F4*2+H4*2.5+J4+L4 -> 24 | P4: Link | S4: 2 | T4: 3525-850 | U4: 3525-850 | V4: 3525-850
A5: 4 | B5: 4225-610 | C5: 15.4 | D5: 3 | E5: 1910 | F5: 1 | G5: 1791 | H5: 3 | I5: 37 | J5: 3 | K5: 12x3 - 12x6 | L5: 4 | M5: =D5+F5+H5+J5+L5 -> 14 | N5: =D5*5+F5*3+H5*4+J5+L5*2 -> 41 | O5: =D5*3+F5*2+H5*2.5+J5+L5 -> 25.5 | P5: Link | S5: 1 | T5: 4225-610 | U5: 4225-610 | V5: 4225-610
M6: =NOW() -> 41741.599 | V6: =NOW() -> 41741.599
