Workbook
Name Acc_Brand: '11. Accessories'!$B$3:$B$4
Name Acc_Link: '11. Accessories'!$S$3:$S$4
Name Acc_Mass: '11. Accessories'!$K$3:$K$4
Name Acc_Model: '11. Accessories'!$D$3:$D$4
Name Acc_Price: '11. Accessories'!$R$3:$R$4
Name Bat_Brand: '9. Batteries'!$B$3:$B$26
Name Bat_Link: '9. Batteries'!$Q$3:$Q$26
Name Bat_Mass: '9. Batteries'!$L$3:$L$26
Name Bat_Model: '9. Batteries'!$C$3:$C$26
Name Bat_Price: '9. Batteries'!$M$3:$M$26
Name Cam_Brand: #REF!
Name Cam_Link: '5. Cameras'!$K$3:$K$13
Name Cam_Mass: #REF!
Name Cam_Model: #REF!
Name Cam_Price: #REF!
Name Camera_Brand: '5. Cameras'!$B$3:$B$13
Name Camera_Model: '5. Cameras'!$C$3:$C$13
Name Camera_Price: '5. Cameras'!$J$3:$J$13
Name ESC_Brand: '8. ESCs'!$B$3:$B$27
Name ESC_Link: '8. ESCs'!$K$3:$K$32
Name ESC_Mass: '8. ESCs'!$H$3:$H$27
Name ESC_Model: '8. ESCs'!$E$3:$E$27
Name ESC_Model2: '8. ESCs'!$C$3:$C$27
Name ESC_Model3: '8. ESCs'!$C$3:$C$32
Name ESC_Price: '8. ESCs'!$J$3:$J$27
Name FC_Brand: '2. Flight Controllers'!$B$3:$B$9
Name FC_Link: '2. Flight Controllers'!$K$3:$K$9
Name FC_Mass: '2. Flight Controllers'!$I$3:$I$9
Name FC_Model: '2. Flight Controllers'!$C$3:$C$9
Name FC_Price: '2. Flight Controllers'!$J$3:$J$9
Name Frame_Brand: '1. Multirotor Frames'!$B$3:$B$27
Name Frame_Line: '1. Multirotor Frames'!$C$3:$C$27
Name Frame_Link: '1. Multirotor Frames'!$Q$3:$Q$27
Name Frame_Mass: '1. Multirotor Frames'!$F$3:$F$27
Name Frame_Model: '1. Multirotor Frames'!$D$3:$D$27
Name Frame_Price: '1. Multirotor Frames'!$P$3:$P$27
Name Framemass: '1. Multirotor Frames'!$F$3:$F$27
Name Gimbal_Brand: '6. Gimbals'!$H$6
Name Gimbal_Brand2: '6. Gimbals'!$B$3:$B$13
Name Gimbal_Link: '6. Gimbals'!$I$3:$I$13
Name Gimbal_Mass: '6. Gimbals'!$G$3:$G$13
Name Gimbal_Model: '6. Gimbals'!$C$3:$C$13
Name Gimbal_Price: '6. Gimbals'!$H$3:$H$13
Name Motor_Brand: '7. Motors'!$B$2:$B$49
Name Motor_Link: '7. Motors'!$S$2:$S$49
Name Motor_Mass: '7. Motors'!$P$2:$P$49
Name Motor_Model: '7. Motors'!$D$2:$D$49
Name Motor_Price: '7. Motors'!$R$2:$R$49
Name Number_of_Motors: '1. Multirotor Frames'!$E$3:$E$27
Name Prop_Brand: '10. Propellers'!$B$3:$B$42
Name Prop_Link: '10. Propellers'!$N$3:$N$42
Name Prop_Mass: '10. Propellers'!$J$3:$J$42
Name Prop_Model: '10. Propellers'!$D$3:$D$42
Name Prop_Price: '10. Propellers'!$L$3:$L$42
Name RC_Brand: '4. Receivers'!$B$3:$B$12
Name RC_Link: '4. Receivers'!$L$3:$L$12
Name RC_Mass: '4. Receivers'!$J$3:$J$12
Name RC_Model: '4. Receivers'!$B$3:$B$12
Name RC_Model2: '4. Receivers'!$D$3:$D$12
Name RC_Price: '4. Receivers'!$K$3:$K$12

Sheet BOM Summary
A1: Bill of Materials | K1: =NOW() -> 41834.849
A2: ITEM NO. | B2: CATEGORY | C2: COMPONENT | D2: BRAND | E2: DROP DOWNS: | F2: QTY. | G2: MASS EACH (g) | H2: TOTAL MASS (g) | I2: PRICE EACH | J2: TOTAL PRICE | K2: LINK
A3: 1 | B3: Hardware | C3: Multirotor | D3: =INDEX(Frame_Brand,MATCH(E3,Frame_Model,0)) -> Tarot | E3: TL960A | F3: 1 | G3: =INDEX(Frame_Mass,MATCH(E3,Frame_Model,0)) -> 1200 | H3: =G3*F3 -> 1200 | I3: =INDEX(Frame_Price,MATCH(E3,Frame_Model,0)) -> 444 | J3: =I3*F3 -> 444 | K3: =INDEX(Frame_Link,MATCH(E3,Frame_Model,0)) -> www.myrcmodel.com
A4: 2 | B4: Electronics | C4: Flight Contoller | D4: =INDEX(FC_Brand,MATCH(E4,FC_Model,0)) -> 3DRobotics | E4: Pixhawk | F4: 1 | G4: =INDEX(FC_Mass,MATCH(E4,FC_Model,0)) -> 54.8 | H4: =G4*F4 -> 54.8 | I4: =INDEX(FC_Price,MATCH(E4,FC_Model,0)) -> 379.98 | J4: =I4*F4 -> 379.98 | K4: =INDEX(FC_Link,MATCH(E4,FC_Model,0)) -> https://store.3drobotics.com
A5: 3 | B5: Electronics | C5: Transmitter | D5: =INDEX(Tx_Brand,MATCH(E5,Tx_Model,0)) -> Futaba | E5: T8FG Super | F5: 1 | G5: 0 | H5: 0 | I5: =INDEX(Tx_Price,MATCH(E5,Tx_Model,0)) -> 479 | J5: =I5*F5 -> 479 | K5: =INDEX(Tx_Link,MATCH(E5,Tx_Model,0)) -> http://www.futaba-rc.com
A6: 4 | B6: Electronics | C6: Receiver | D6: =INDEX(RC_Brand,MATCH(E6,RC_Model2,0)) -> Futaba | E6: R6208SB | F6: 1 | G6: =INDEX(RC_Mass,MATCH(E6,RC_Model2,0)) -> 13.8 | H6: =G6*F6 -> 13.8 | I6: =INDEX(RC_Price,MATCH(E6,RC_Model2,0)) -> 129.99 | J6: =I6*F6 -> 129.99 | K6: =INDEX(RC_Link,MATCH(E6,RC_Model2,0)) -> www.gpdealera.com
A7: 5 | B7: Electronics | C7: Camera | D7: =INDEX(Camera_Brand,MATCH(E7,Camera_Model,0)) -> Cannon | E7: 5D Mark III with 24mm f/2.8 | F7: 1 | G7: =INDEX('5. Cameras'!I3:I13,MATCH(E7,Camera_Model,0)) -> 1244 | H7: =G7*F7 -> 1244 | I7: =INDEX(Camera_Price,MATCH(E7,Camera_Model,0)) -> 3399 | J7: =I7*F7 -> 3399 | K7: =INDEX(Cam_Link,MATCH(E7,Camera_Model,0)) -> www.usa.canon.com
A8: 6 | B8: Electronics | C8: Gimbal | D8: =INDEX(Gimbal_Brand2,MATCH(E8,Gimbal_Model,0)) -> DJI | E8: Z15 - 5D | F8: 1 | G8: =INDEX(Gimbal_Mass,MATCH(E8,Gimbal_Model,0)) -> 1420 | H8: =G8*F8 -> 1420 | I8: =INDEX(Gimbal_Price,MATCH(E8,Gimbal_Model,0)) -> 2999 | J8: =I8*F8 -> 2999 | K8: =INDEX(Gimbal_Link,MATCH(E8,Gimbal_Model,0)) -> www.dji.com
A9: 7 | B9: Electronics | C9: Motor | D9: =INDEX(Motor_Brand,MATCH(E9,Motor_Model,0)) -> Tiger | E9: U5-400 | F9: =INDEX(Number_of_Motors, MATCH(E3,Frame_Model,0)) -> 6 | G9: =INDEX(Motor_Mass,MATCH(E9,Motor_Model,0)) -> 156 | H9: =G9*F9 -> 936 | I9: =INDEX(Motor_Price,MATCH(E9,Motor_Model,0)) -> 125.9 | J9: =I9*F9 -> 755.4 | K9: =INDEX(Motor_Link,MATCH(E9,Motor_Model,0)) -> www.rctigermotor.com
A10: 8 | B10: Electronics | C10: ESC | D10: =INDEX(ESC_Brand,MATCH(E10,ESC_Model2,0)) -> T-Motor | E10: S 35A | F10: =F9 -> 6 | G10: =INDEX(ESC_Mass,MATCH(E10,ESC_Model2,0)) -> 30 | H10: =G10*F10 -> 180 | I10: =INDEX(ESC_Price,MATCH(E10,ESC_Model2,0)) -> 29.99 | J10: =I10*F10 -> 179.94 | K10: =INDEX(ESC_Link,MATCH(E10,ESC_Model3,0)) -> http://www.diyquadcopters.com
A11: 9 | B11: Electronics | C11: Battery | D11: =INDEX(Bat_Brand,MATCH(E11,Bat_Model,0)) -> Xaircraft | E11: 5800mAh 4S 35C | F11: 2 | G11: =INDEX(Bat_Mass,MATCH(E11,Bat_Model,0)) -> 585 | H11: =G11*F11 -> 1170 | I11: =INDEX(Bat_Price,MATCH(E11,Bat_Model,0)) -> 90 | J11: =I11*F11 -> 180 | K11: =INDEX(Bat_Link,MATCH(E11,Bat_Model,0)) -> http://xaircraftamerica.com
A12: 10 | B12: Hardware | C12: Propellers | D12: =INDEX(Prop_Brand,MATCH(E12,Prop_Model,0)) -> Gemfan | E12: GF 12x5.5 | F12: 5 | G12: =INDEX(Prop_Mass,MATCH(E12,Prop_Model,0)) -> 15 | H12: =G12*$F$9 -> 90 | I12: =INDEX(Prop_Price,MATCH(E12,Prop_Model,0)) -> 20 | J12: =I12*F12 -> 100 | K12: =INDEX(Prop_Link,MATCH(E12,Prop_Model,0)) -> http://www.diyquadcopters.com
A13: 11 | B13: Hardware | C13: Accessories | D13: =INDEX(Acc_Brand,MATCH(E13,Acc_Model,0)) -> Spot | E13: Trace | F13: 1 | G13: =INDEX(Acc_Mass,MATCH(E13,Acc_Model,0)) -> 88 | H13: =G13*F13 -> 88 | I13: =INDEX(Acc_Price,MATCH(E13,Acc_Model,0)) -> 199.84 | J13: =I13*F13 -> 199.84 | K13: =INDEX(Acc_Link,MATCH(E13,Acc_Model,0)) -> www.findmespot.com
A14: TOTALS | G14: Mass: | H14: =SUM(H3:H13) -> 6396.6 | I14: Price: | J14: =SUM(J3:J13) -> 9246.15
I15: Less what I already own: | J15: =J14-J5-J7 -> 5368.15
A16: Round 0: Potential Combinations | E16: Round 1 | F16: Round 2 | G16: Round 3 | H16: Round 4 | I16: Round 5 | J16: Round 6 | K16: Components Selected During:
A17: ITEM NO. | B17: CATEGORY | C17: COMPONENT | D17: OPTIONS | E17: 4/5/14 11:15AM | F17: 4/7/14 8:51PM | G17: 41738.542 | H17: 4/12/14 11:27PM | I17: 4/14/14 4:24PM | J17: 4/16/14 10:26AM | K17: Round 1 (4 items)
A18: 1 | B18: Frame | C18: Multirotor | D18: 21 | E18: 9 | F18: 3 | G18: 1 | H18: 1 | I18: 1 | J18: 1 | K18: Round 2 (0 items)
A19: 2 | B19: Electronics | C19: Flight Contoller | D19: 7 | E19: 5 | F19: 3 | G19: 1 | H19: 1 | I19: 1 | J19: 1 | K19: Round 3 (3 Items)
A20: 3 | B20: Electronics | C20: Transmitter | D20: 13 | E20: 1 | F20: 1 | G20: 1 | H20: 1 | I20: 1 | J20: 1 | K20: Round 4 (0 Items)
A21: 4 | B21: Electronics | C21: Receiver | D21: 8 | E21: 1 | F21: 1 | G21: 1 | H21: 1 | I21: 1 | J21: 1 | K21: Round 5 (3 Items)
A22: 5 | B22: Accessories | C22: Camera | D22: 7 | E22: 1 | F22: 1 | G22: 1 | H22: 1 | I22: 1 | J22: 1 | K22: Round 6 (1 Items)
A23: 6 | B23: Accessories | C23: Gimbal | D23: 7 | E23: 5 | F23: 3 | G23: 1 | H23: 1 | I23: 1 | J23: 1
A24: 7 | B24: Electronics | C24: Motor | D24: 37 | E24: 20 | F24: 15 | G24: 11 | H24: 2 | I24: 1 | J24: 1
A25: 8 | B25: Electronics | C25: ESC | D25: 23 | E25: 23 | F25: 17 | G25: 10 | H25: 3 | I25: 1 | J25: 1
A26: 9 | B26: Electronics | C26: Battery | D26: 17 | E26: 17 | F26: 11 | G26: 7 | H26: 5 | I26: 1 | J26: 1
A27: 10 | B27: Hardware | C27: Propellers | D27: 28 | E27: 28 | F27: 20 | G27: 20 | H27: 19 | I27: 17 | J27: 1
A28: 11 | B28: Accessories | C28: GPS Tracker | D28: 1 | E28: 1 | F28: 1 | G28: 1 | H28: 1 | I28: 1 | J28: 1
C29: # OF TOTAL POSSIBLE COMBINATIONS: | D29: =D18*D19*D20*D21*D22*D23*D24*D25*D26*D27 -> 303447292512 | E29: =E18*E19*E20*E21*E22*E23*E24*E25*E26*E27 -> 49266000 | F29: =F18*F19*F20*F21*F22*F23*F24*F25*F26*F27 -> 1514700 | G29: =G18*G19*G20*G21*G22*G23*G24*G25*G26*G27 -> 15400 | H29: =H18*H19*H20*H21*H22*H23*H24*H25*H26*H27 -> 570 | I29: =I18*I19*I20*I21*I22*I23*I24*I25*I26*I27 -> 17 | J29: =J18*J19*J20*J21*J22*J23*J24*J25*J26*J27 -> 1
D30: % Reduction: | E30: =(1-(49266000/D29))*100 -> 99.983765 | F30: =(1-(F29/E29))*100 -> 96.925466 | G30: =(1-(G29/F29))*100 -> 98.983297 | H30: =(1-(H29/G29))*100 -> 96.298701 | I30: =(1-(I29/H29))*100 -> 97.017544 | J30: =(1-(J29/I29))*100 -> 94.117647
A31: This Round: Potential Combinations
A32: ITEM NO. | B32: CATEGORY | C32: COMPONENT | D32: OPTIONS
A33: 1 | B33: Hardware | C33: Multirotor | D33: ='1. Multirotor Frames'!A27 -> 1
A34: 2 | B34: Electronics | C34: Flight Contoller | D34: ='2. Flight Controllers'!A9 -> 1
A35: 3 | B35: Electronics | C35: Transmitter | D35: ='3. Transmitters'!A17 -> 1
A36: 4 | B36: Electronics | C36: Receiver | D36: ='4. Receivers'!A12 -> 1
A37: 5 | B37: Accessories | C37: Camera | D37: ='5. Cameras'!A13 -> 1
A38: 6 | B38: Accessories | C38: Gimbal | D38: ='6. Gimbals'!A13 -> 1
A39: 7 | B39: Electronics | C39: Motor | D39: ='7. Motors'!A49 -> 1
A40: 8 | B40: Electronics | C40: ESC | D40: ='8. ESCs'!A32 -> 1
...

Sheet Budget
A1: Money Spent
A2: Vendor | B2: Items | C2: Estimated Cost | D2: Actual Cost | E2: Possible Savings
A3: WHCC Order # | B3: Photo Prints | C3: 442.56 | D3: 474.76 | F3: x
A4: WHCC Order # | B4: Photo Prints 2
A5: Artsy Couture Order 4/17/14 | B5: Canvas Wraps Batch 1 | C5: 68.78 | D5: 68.78 | F5: x
A6: Artsy Couture Order 4/?/14 | B6: Canvas Wraps Batch 2 | C6: 68.78
A7: diyquadcopters.com Order # | B7: Motors, ESCs, Props | C7: 939 | E7: 160
A8: FlySafe Training | B8: Training | C8: 729.92 | D8: 729.92 | F8: x
A9: Helipal.com Order # | B9: Frame, FPV | C9: 941.89 | D9: 941.89 | F9: x
A10: xaircraftamerica.com Order # | B10: Batteries | C10: 360 | D10: 360 | F10: x
A11: Shipping Expenses | B11: Packaging and Postage | C11: =114.39+43.65+44.46 -> 202.5 | D11: =114.39+43.65+44.46 -> 202.5
A12: Shipping Expenses Round 2
A13: 3drobotics.com | B13: FC, Telemetry | C13: 420.22 | D13: 420.22 | F13: x
A14: rcplanet.com | B14: Receivers | C14: 129.99 | D14: 129.99 | F14: x
A15: bhphotovideo.com | B15: H3-3D Gimbal | C15: 369 | D15: 369
A16: Accessories | B16: Spot Trace - GPS Tracker | C16: 107.22 | D16: =107.22+117.98 -> 225.2 | F16: x
A17: Total Expenses: | C17: =SUM(C3:C16) -> 4779.86 | D17: =SUM(D3:D16) -> 3922.26 | E17: =SUM(E3:E16) -> 160
A18: Funds remaining: | C18: =B26-C17 -> -141.4 | D18: =B26-D17 -> 716.2
A22: Transfer
A23: 41745 | B23: 3700
A24: 41745 | B24: 800
B25: 138.46
A26: Funds | B26: =SUM(B23:B25) -> 4638.46

Sheet Thank you Round
A1: x | B1: Dennis | C1: Pernu | D1: Option 2 – 8x10 – Grain Belt Beer
A2: x | B2: Patrick | C2: Fuentes | D2: Option 2 – 11x14 – Grain Belt Beer
A3: x | B3: Justina | C3: Christiansen | D3: Option 2 – 12x18 – Grain Belt Beer
A4: x | B4: Joel | C4: Wuorio | D4: Option 2 – 12x18 – Grain Belt Beer
A5: x | B5: Will | C5: Mitchel | D5: Option 6 – 11x14 – Downtown Minneapolis #2
B6: Sandy | C6: Wuorio | D6: Option 2 – 8x10 – Grain Belt Beer
A7: x | B7: Kevin | C7: Hoffman | D7: Option 7 – 8x10 – Downtown Minneapolis #3 | E7: 401 N. 3rd St. Suite 550, Minneapolis, MN 55401
A8: x | B8: Brandon | C8: Vasquez | D8: Option 2 – 8x10 – Grain Belt Beer | E8: Meet Minneapolis Attn Brandon Vasquez 250 Marquette Avenue South, Suite 1300 Minneapolis, MN 55401
A9: x | B9: Brandon's | C9: Co-Worker | D9: Option 7 – 8x10 – Downtown Minneapolis #3
A10: x | B10: Chad | C10: Pelarksi | D10: Option 2 – 11x14 – Grain Belt Beer | E10: Option 1 – 11x14 – Ramp Spiral #1 | F10: Option 7 – 11x14 – Downtown Minneapolis #3 | G10: Option 8 – 8x10 – Target HQ
A11: x | B11: Andrew | C11: Morris | D11: Option 3 – 11x14 – Downtown Minneapolis #1 | E11: Option 2 – 11x14 – Grain Belt Beer | F11: Option 4 – 11x14 – Minneapolis from Loring Park | G11: Option 8 – 8x10 – Target HQ
A12: x | B12: Gayle | C12: Koop | D12: Option 6 – 11x14 – Downtown Minneapolis #2 | E12: Option 7 – 11x14 – Downtown Minneapolis #3 | F12: Option 4 – 11x14 – Minneapolis from Loring Park | G12: Option 5 - 8x10 - Downtown Saint Paul
A13: x | B13: Gwenne | C13: Gustafson | D13: Option 3 – 11x14 – Downtown Minneapolis #1 | E13: Option 6 – 11x14 – Downtown Minneapolis #2 | F13: Option 7 – 11x14 – Downtown Minneapolis #3 | G13: Option 2 – 8x10 – Grain Belt Beer
A14: x | B14: Aviv | C14: Baron | D14: Option 1 – 8x10 – Ramp Spiral #1
B15: Kirstie | C15: Kimball | D15: Option 2 – 8x10 – Grain Belt Beer

Sheet Sheet1
A1: Option 1 – 11x14 – Ramp Spiral #1 | B1: x
A2: Option 1 – 8x10 – Ramp Spiral #1 | B2: x
A3: Option 2 – 11x14 – Grain Belt Beer | B3: x
A4: Option 2 – 11x14 – Grain Belt Beer | B4: x
A5: Option 2 – 11x14 – Grain Belt Beer | B5: x
A6: Option 2 – 12x18 – Grain Belt Beer | B6: x
A7: Option 2 – 12x18 – Grain Belt Beer | B7: x
A8: Option 2 – 8x10 – Grain Belt Beer | B8: x
A9: Option 2 – 8x10 – Grain Belt Beer | B9: x
A10: Option 2 – 8x10 – Grain Belt Beer | B10: x
A11: Option 2 – 8x10 – Grain Belt Beer | B11: x
A12: Option 2 – 8x10 – Grain Belt Beer | B12: x
... A27: Option 8 – 8x10 – Target HQ | B27: x

Sheet 1. Multirotor Frames
A1: Multirotor Frames
A2: Option | B2: Brand | C2: Line | D2: Model | E2: # of Motors | F2: Frame Mass (g) | G2: Between Motor Centers (mm) | H2: Between Motor Centers (in) | I2: Material | J2: Country of Origin | K2: Retractable Landing Gear Option? | L2: Max Propeller Size | M2: Foldable? | N2: Stock Frame Fits Gimbal? | O2: Payload Limit (KG) | P2: Price (US$) | Q2: Link
A3: 21 | B3: Aeronavics | C3: Airframe | D3: XM-6 Ti-QR | E3: 6 | F3: ? | G3: 770 | H3: =G3/25.4 -> 30.314961 | I3: CF | J3: New Zealand | K3: Y | L3: 14 | M3: Y | N3: Y | O3: ? | P3: 1922.69 | Q3: www.aeronavics.com
B4: Aeronavics | C4: Airframe | D4: XM-8 Ti-QR | E4: 8 | F4: 2415 | G4: 940 | H4: =G4/25.4 -> 37.007874 | I4: CF | J4: New Zealand | K4: Y | L4: 13 | M4: Y | N4: Y | O4: ? | P4: 2091.57 | Q4: www.aeronavics.com
B5: Aeronavics | C5: SkyJib | D5: 6 Ti-QR | E5: 6 | F5: ? | G5: 1080 | H5: =G5/25.4 -> 42.519685 | I5: CF | J5: New Zealand | K5: Y | L5: 17 | M5: Y | N5: Y | O5: ? | P5: 2684.83 | Q5: www.aeronavics.com
B6: Aeronavics | C6: SkyJib | D6: 8 Ti-QR | E6: 8 | F6: ? | G6: 1160 | H6: =G6/25.4 -> 45.669291 | I6: CF | J6: New Zealand | K6: Y | L6: 15 | M6: Y | N6: Y | O6: ? | P6: 3057.25 | Q6: www.aeronavics.com
B7: Aeronavics | C7: SkyJib | D7: X4 Ti-QR | E7: 8 | F7: ? | G7: 900 | H7: =G7/25.4 -> 35.433071 | I7: CF | J7: New Zealand | K7: Y | L7: 15 | M7: Y | N7: Y | O7: ? | P7: 2702.15 | Q7: www.aeronavics.com
B9: Arris | C9: Hexacopter | D9: M1000 | E9: 6 | F9: ? | G9: 1000 | H9: =G9/25.4 -> 39.370079 | I9: CF | J9: China | K9: N | L9: ? | M9: N | N9: Y | O9: ? | P9: 350 | Q9: www.hobby-wing.com
B10: Arris | C10: Hexacopter | D10: M1050 | E10: 6 | F10: 1400 | G10: 1050 | H10: =G10/25.4 -> 41.338583 | I10: CF | J10: China | K10: N | L10: 17 | M10: Y | N10: Y | O10: ? | P10: 349 | Q10: www.hobby-wing.com
B11: Arris | C11: Hexacopter | D11: M680 | E11: 6 | F11: ? | G11: 680 | H11: =G11/25.4 -> 26.771654 | I11: CF | J11: China | K11: N | L11: ? | M11: Y | N11: Y | O11: ? | P11: 195 | Q11: www.hobby-wing.com
B13: Carboncore | C13: Hexacopter | D13: Hex 650 | E13: 6 | F13: 720 | G13: 650 | H13: =G13/25.4 -> 25.590551 | I13: CF | J13: United Kingdom | K13: N | L13: ? | M13: N | N13: Y | O13: 6 total | P13: 549 | Q13: www.coptersquad.com
B14: Carboncore | C14: Hexacopter | D14: Hex 950 | E14: 6 | F14: 780 | G14: 950 | H14: =G14/25.4 -> 37.401575 | I14: CF | J14: United Kingdom | K14: N | L14: ? | M14: N | N14: Y | O14: 8 total | P14: 590 | Q14: www.coptersquad.com
B15: Carboncore | C15: Octocopter | D15: X8 650 Quad | E15: 8 | F15: 600 | G15: 650 | H15: =G15/25.4 -> 25.590551 | I15: CF | J15: United Kingdom | K15: N | L15: ? | M15: N | N15: N | O15: ? | P15: 385 | Q15: www.rc-drones.com
B16: Carboncore | C16: Octocopter | D16: X8 950 Quad | E16: 8 | F16: 655 | G16: 950 | H16: =G16/25.4 -> 37.401575 | I16: CF | J16: United Kingdom | K16: N | L16: ? | M16: N | N16: N | O16: ? | P16: 435 | Q16: www.rc-drones.com
B17: Carboncore | C17: X8 Co-Axial | D17: Cortex | E17: 8 | F17: 1230 | G17: 800 | H17: =G17/25.4 -> 31.496063 | I17: CF | J17: United Kingdom | K17: N | L17: ? | M17: Y | N17: Y | O17: ? | P17: 1100 | Q17: www.shop.carboncore.co.uk
B19: DJI | C19: Spreading Wings | D19: S1000 | E19: 8 | F19: 4200 | G19: 1000 | H19: =G19/25.4 -> 39.370079 | I19: CF | J19: China | K19: Y | L19: 15 | M19: Y | N19: Y | O19: 5.8 | P19: 3939 | Q19: www.dji.com
B20: DJI | C20: Spreading Wings | D20: S800 EVO | E20: 6 | F20: 3700 | G20: 800 | H20: =G20/25.4 -> 31.496063 | I20: CF | J20: China | K20: Y | L20: 15 | M20: N | N20: Y | O20: 4.3 | P20: 2999 | Q20: www.dji.com
B22: Tarot | C22: Hexacopter | D22: TL810A | E22: 6 | F22: 1020 | G22: 850 | H22: =G22/25.4 -> 33.464567 | I22: CF | J22: China | K22: N | L22: 15 | M22: Y | N22: Y | O22: 3 | P22: =339+105 -> 444 | Q22: www.myrcmodel.com
A23: 1 | B23: Tarot | C23: Hexacopter | D23: TL960A | E23: 6 | F23: 1200 | G23: 960 | H23: =G23/25.4 -> 37.795276 | I23: CF | J23: China | K23: N | L23: 18 | M23: Y | N23: Y | O23: 3.5 | P23: =339+105 -> 444 | Q23: www.myrcmodel.com
B24: Tarot | C24: Octocopter | D24: T15 | E24: 8 | F24: 1950 | G24: 1020 | H24: =G24/25.4 -> 40.15748 | I24: CF | J24: China | K24: N | L24: 15 | M24: Y | N24: Y | O24: 11 total | P24: 619 | Q24: www.myrcmodel.com
B25: Tarot | C25: Hexacopter | D25: FY680 | E25: 6 | F25: 600 | G25: 680 | H25: =G25/25.4 -> 26.771654 | I25: CF | J25: China | K25: N | L25: 13 | M25: Y | N25: Y | O25: ? | P25: 169.99 | Q25: www.myrcmodel.com
B26: Tarot | C26: Hexacopter | D26: FY690S | E26: 6 | F26: 600 | G26: 690 | H26: =G26/25.4 -> 27.165354 | I26: CF | J26: China | K26: N | L26: 13 | M26: Y | N26: Y | O26: ? | P26: 199 | Q26: www.myrcmodel.com
A27: 1 | B27: Tarot | C27: Octocopter | D27: IRON MAN 1000 | E27: 8 | F27: 1500 | G27: 1020 | H27: =G27/25.4 -> 40.15748 | I27: CF | J27: China | K27: N | L27: 15 | M27: N | N27: Y | O27: 8 | P27: 399 | Q27: www.myrcmodel.com
E28: Minimums: | F28: =MIN(F3:F27) -> 600 | G28: =MIN(G3:G27) -> 650 | H28: =MIN(H3:H27) -> 25.590551 | L28: =MIN(L3:L27) -> 13 | P28: =MIN(P9:P16,P22:P27) -> 169.99 | Q28: =NOW() -> 41834.849
E29: Maximums: | F29: =MAX(F3:F27) -> 4200 | G29: =MAX(G3:G27) -> 1160 | H29: =MAX(H3:H27) -> 45.669291 | L29: =MAX(L3:L27) -> 18 | P29: =MAX(P9:P16,P22:P27) -> 619
E30: Averages: | F30: =AVERAGE(Frame_Mass) -> 1504.6667 | G30: =AVERAGE(G3:G27) -> 885.71429 | H30: =AVERAGE(H3:H27) -> 34.870641 | L30: =AVERAGE(L3:L27) -> 15 | P30: =AVERAGE(P9:P16,P22:P27) -> 394.46077
B31: Elimination
B32: Round 1: | C32: Round 2: | D32: Round 3:
B33: High Price | C33: 8 Motors | D33: Too Heavy
B34: Small Size | C34: Not Foldable | D34: Payload < 3.5
D35: Selected

Sheet 2. Flight Controllers
A1: Flight Controllers
A2: Option | B2: Brand | C2: Model | D2: GPS included? | E2: LED included? | F2: Gimbal Compatible? | G2: Program via computer? | H2: # of Battery Cells: | I2: Mass (g) | J2: Price (US$) | K2: Link
A3: 7 | B3: 3DRobotics | C3: APM 2.6 Set | D3: ? | E3: N | F3: Y | G3: ? | H3: ? | I3: 0 | J3: 339.98 | K3: https://store.3drobotics.com
A4: 1 | B4: 3DRobotics | C4: Pixhawk | D4: ? | E4: N | F4: Y | G4: ? | H4: ? | I4: =38+16.8 -> 54.8 | J4: 379.98 | K4: https://store.3drobotics.com
B5: DJI | C5: A2 | D5: Y | E5: Y | F5: Y | G5: Y | H5: 2 - 6 | I5: 224 | J5: 1299 | K5: http://www.dji.com/product/a2
B6: DJI | C6: Naza-M V2 | D6: Y | E6: Y | F6: Y | G6: Y | H6: 2 - 6 | I6: 95 | J6: 299 | K6: http://www.dji.com/product/naza-m-v2
B7: DJI | C7: Wookong-M | D7: Y | E7: ? | F7: Y | G7: Y | H7: 2 - 6 | I7: 118 | J7: 999 | K7: http://www.dji.com/product/wookong-m
B8: Feiyu Tech | C8: FY41AP GPS & OSD | D8: Y | E8: N | F8: Y | G8: Y | H8: 2 - 6 | I8: 220 | J8: 412 | K8: http://www.coptersquad.com
A9: 1 | B9: Feiyu Tech | C9: FYDosAutopilot | D9: ? | E9: N | F9: Y | G9: Y | I9: 220 | J9: 275 | K9: http://www.coptersquad.com
H10: Min: | I10: =MIN(FC_Mass) -> 0 | J10: =MIN(FC_Price) -> 275 | K10: =NOW() -> 41834.849
H11: Max: | I11: =MAX(FC_Mass) -> 224 | J11: =MAX(FC_Price) -> 1299
B12: Elimination | H12: Avg: | I12: =AVERAGE(FC_Mass) -> 133.11429 | J12: =AVERAGE(FC_Price) -> 571.99429
B13: Round 1: | C13: Round 2:
B14: High Price | C14: Unfamiliar
B16: Round 3:
B17: Pixhawk is newer
B18: Want to try competitor
B19: Selected

Sheet 3. Transmitters
A1: Transmitters
A2: Option | B2: Brand | C2: Model | D2: Radio Spectrum | E2: # of Channels | F2: Memory Card? | G2: Type | H2: Mode 2 available? | I2: Recommened Receiver | J2: LCD Screen? | K2: Price | L2: Link
A3: 13 | B3: Futaba | C3: 14SG | D3: 2.4GHz | E3: 14 | F3: SD | G3: FASST | H3: Y | I3: R6014HS | J3: Y | K3: 599 | L3: http://www.futaba-rc.com/systems/futk9410-14sg/index.html
A4: 1 | B4: Futaba | C4: T8FG Super | D4: 2.4GHz | E4: 14 | F4: SD | G4: FASST | H4: Y | I4: R6208SB | J4: Y | K4: 479 | L4: http://www.futaba-rc.com
B5: Futaba | C5: 10CG | D5: 2.4GHz | E5: 10 | F5: ? | G5: FASST | H5: Y | I5: R6014HS | J5: Y | K5: 549.9 | L5: http://www.futaba-rc.com/systems/futk9255.html
B6: Futaba | C6: 7C | D6: 2.4GHz | E6: 7 | F6: None | G6: FASST | H6: Y | I6: R617FS | J6: Y | K6: 279.99 | L6: http://www.futaba-rc.com/systems/futk7000.html
B7: Futaba | C7: 6EX | D7: 2.4GHz | E7: 6 | F7: None | G7: FASST | H7: Y | I7: R617FS | J7: Y | K7: 212.08 | L7: http://www.futaba-rc.com/systems/futk6900.html
B9: JR | C9: XG14 | D9: 2.4GHz | E9: 14 | F9: SD | G9: DMSS | H9: Y | I9: RG1131B | J9: Y | K9: 679 | L9: http://www.jramericas.com/233795/JRP00632/?pcat=2
B10: JR | C10: XG11 | D10: 2.4GHz | E10: 11 | F10: SD | G10: DMSS | H10: Y | I10: RG1131B | J10: Y | K10: 799 | L10: http://www.jramericas.com/211277/JRP00615/?pcat=2
B11: JR | C11: XG8 | D11: 2.4GHz | E11: 8 | F11: SD | G11: DMSS | H11: Y | I11: RG731B | J11: Y | K11: 429 | L11: http://www.jramericas.com/211276/JRP00596/?pcat=2
B12: JR | C12: XG6 | D12: 2.4GHz | E12: 6 | F12: microSD | G12: DMSS | H12: Y | I12: RG631B | J12: Y | K12: 199 | L12: http://www.jramericas.com/211278/JRP00619/?pcat=2
B14: Spektrum | C14: DX9 | D14: 2.4GHz | E14: 9 | F14: SD | G14: DSM2/DSMX | H14: Y | I14: ? | J14: Y | K14: 449.99 | L14: http://www.spektrumrc.com/Products/Default.aspx?ProdId=SPMR9900
B15: Spektrum | C15: DX8 | D15: 2.4GHz | E15: 8 | F15: SD | G15: DSM2/DSMX | H15: Y | I15: ? | J15: Y | K15: 299.99 | L15: http://www.spektrumrc.com/Products/Default.aspx?ProdId=SPMR8810
B16: Spektrum | C16: DX7s | D16: 2.4GHz | E16: 7 | F16: SD | G16: DSM2/DSMX | H16: Y | I16: AR8000 | J16: Y | K16: 299.99 | L16: http://www.spektrumrc.com/Products/Default.aspx?ProdId=SPM7800
A17: 1 | B17: Spektrum | C17: DX6 | D17: 2.4GHz | E17: 6 | F17: SD | G17: DSM2/DSMX | H17: Y | I17: AR610 | J17: Y | K17: 229.99 | L17: http://www.spektrumrc.com/Products/Default.aspx?ProdId=SPM6700
C18: Min: | E18: =MIN(E3:E17) -> 6 | K18: =MIN(K3:K17) -> 199 | L18: =NOW() -> 41834.849
C19: Max: | E19: =MAX(E3:E17) -> 14 | K19: =MAX(K3:K17) -> 799
C20: Avg: | E20: =AVERAGE(E3:E17) -> 9.2307692 | K20: =AVERAGE(K3:K17) -> 423.53308
B22: Elimination
B23: Round 1:
B24: Already Own

Sheet 4. Receivers
A1: Receivers
A2: Option | B2: Brand | C2: Line | D2: Model | E2: # of channels | F2: Length (mm) | G2: Width (mm) | H2: Height (mm) | I2: Operating Voltage | J2: Mass (grams) | K2: Price (US$) | L2: Link
A3: 8 | B3: Futaba | C3: FASST 2.4GHz | D3: R6014HS | E3: 14 | F3: 52 | G3: 37.6 | H3: 15.9 | I3: 4.8-6 | J3: 21.5 | K3: 169.98 | L3: www.gpdealera.com
A4: 1 | B4: Futaba | C4: FASST 2.4GHz | D4: R6208SB | E4: 8 | F4: 47.3 | G4: 24.9 | H4: 14.3 | I4: 3.7-7.4 | J4: 13.8 | K4: 129.99 | L4: www.gpdealera.com
B5: Futaba | C5: FASST 2.4GHz | D5: R617FS | E5: 7 | F5: 40 | G5: 27 | H5: 9 | I5: 4.8-6 | J5: 9.8 | K5: 69.95 | L5: www.gpdealera.com
B7: JR | C7: DMSS 2.4GHz | D7: RG1131B | E7: 11 | F7: 47.5 | G7: 32 | H7: 14 | I7: 4.5-8.5 | J7: 18 | K7: 129.99 | L7: www.horizonhobby.com
B8: JR | C8: DMSS 2.4GHz | D8: RG631B | E8: 6 | F8: 46.5 | G8: 20 | H8: 12.5 | I8: 4.8-8.5 | J8: 9 | K8: 79.99 | L8: www.horizonhobby.com
B10: Spektrum | C10: DSMX 2.4 GHz | D10: AR8000 | E10: 8 | F10: 34.3 | G10: 32.3 | H10: 11.4 | I10: 3.5-9.6 | J10: 9.4 | K10: 129.99 | L10: www.spektrumrc.com
B11: Spektrum | C11: DSMX 2.4 GHz | D11: AR7610 | E11: 7 | F11: 34.3 | G11: 29.2 | H11: 11.4 | I11: 3.5-9.6 | J11: 8.9 | K11: 89.99 | L11: www.spektrumrc.com
A12: 1 | B12: Spektrum | C12: DSMX 2.4 GHz | D12: AR610 | E12: 6 | F12: 36.6 | G12: 26.7 | H12: 12.7 | I12: ? | J12: 9 | K12: 49.99 | L12: www.spektrumrc.com
D13: MIN: | E13: =MIN(E3:E12) -> 6 | F13: =MIN(F3:F12) -> 34.3 | G13: =MIN(G3:G12) -> 20 | H13: =MIN(H3:H12) -> 9 | J13: =MIN(J3:J12) -> 8.9 | K13: =MIN(K3:K12) -> 49.99 | L13: =NOW() -> 41834.849
D14: MAX: | E14: =MAX(E3:E12) -> 14 | F14: =MAX(F3:F12) -> 52 | G14: =MAX(G3:G12) -> 37.6 | H14: =MAX(H3:H12) -> 15.9 | J14: =MAX(J3:J12) -> 21.5 | K14: =MAX(K3:K12) -> 169.98
B15: Elimination | D15: AVG: | E15: =AVERAGE(E3:E12) -> 8.375 | F15: =AVERAGE(F3:F12) -> 42.3125 | G15: =AVERAGE(G3:G12) -> 28.7125 | H15: =AVERAGE(H3:H12) -> 12.65 | J15: =AVERAGE(J3:J12) -> 12.425 | K15: =AVERAGE(K3:K12) -> 106.23375
B16: Round 1:
B17: Recommended for my Tx

Sheet 5. Cameras
A1: Cameras
A2: Option | B2: Brand | C2: Model | D2: MegaPixals | E2: Photo? | F2: Video? | G2: Memory Card | H2: Custom Gimbal Available | I2: Mass (grams) | J2: Price (US$) | K2: Link
A3: 7 | B3: Black Magic | C3: Pocket Cinema Cam | D3: 12 | E3: Y | F3: 1080 @ 30fps | G3: SD | H3: Z15 | I3: 355 | J3: 995 | K3: bhphotovideo.com
B5: Cannon | C5: 5D Mark III with 24mm f/2.8 | D5: 22.3 | E5: Y | F5: at? | G5: SD | H5: Z15 | I5: 1244 | J5: 3399 | K5: www.usa.canon.com
A7: 1 | B7: GoPro | C7: Hero 3+ Black | D7: 12 | E7: Y | F7: at? | G7: Micro SD | H7: H3-3D | I7: 74 | J7: 399.99 | K7: http://gopro.com
B8: GoPro | C8: Hero 3+ Silver | D8: 10 | E8: Y | F8: at? | G8: Micro SD | H8: H3-3D | I8: 74 | J8: 299.99 | K8: http://gopro.com/cameras/hd-hero3-silver-edition
B10: Nikon | C10: D300 | D10: 12.3 | E10: Y | F10: N/A | G10: CF | H10: AV200 | I10: 840 | J10: 1596.95 | K10: bhphotovideo.com
B11: Nikon | C11: D800 | D11: 36.3 | E11: Y | F11: 1080 @ 30fps | G11: SD | H11: AV200 | I11: 900 | J11: 2799.95 | K11: www.nikonusa.com
A13: 1 | B13: Panasonic | C13: GH3 | D13: 16 | E13: Y | F13: 1080 @ 60fps | G13: SD | H13: AV130 | I13: 550 | J13: 1298 | K13: bhphotovideo.com
C14: Min: | D14: =MIN(D3:D13) -> 10 | I14: =MIN(I3:I13) -> 74 | J14: =MIN(J3:J13) -> 299.99
C15: Max: | D15: =MAX(D2:D10) -> 22.3 | I15: =MAX(I2:I10) -> 1244 | J15: =MAX(J2:J10) -> 3399
B16: Elimination | C16: Avg: | D16: =AVERAGE(D3:D13) -> 17.271429 | I16: =AVERAGE(I3:I13) -> 576.71429 | J16: =AVERAGE(J3:J13) -> 1541.2686
B17: Round 1:
B18: Selected (Already Own)

Sheet 6. Gimbals
A1: Gimbals
A2: Option | B2: Brand | C2: Model | D2: Supported Cameras | E2: Lipo Cells | F2: # of Axis | G2: Mass (grams) | H2: Price (US$) | I2: Link
A3: 8 | B3: Arris | C3: CM2000 V5.0 | D3: GoPro 3/3+ | E3: 3 | F3: 2 | G3: 240 | H3: 269 | I3: www.hobby-wing.com
B4: Arris | C4: CM3000 | D4: GoPro 3/3+ | E4: 3 | F4: 3 | G4: 252 | H4: 350 | I4: www.hobby-wing.com
B6: DJI | C6: H3-2D | D6: GoPro 3/3+ | E6: 3-6 | F6: 2 | G6: 157 | H6: 369 | I6: www.dji.com
A7: 1 | B7: DJI | C7: H3-3D | D7: GoPro 3/3+ | E7: 3-6 | F7: 3 | G7: 168 | H7: 399 | I7: www.dji.com
B8: DJI | C8: Z15 - 5D | D8: Canon 5D Mark III | E8: 4-12 | F8: 3 | G8: 1420 | H8: 2999 | I8: www.dji.com
B10: PhotoHigher | C10: AV130 | D10: GH2 | E10: ? | F10: 2 | G10: 410 | H10: 869 | I10: www.photohigher.co.nz
B11: PhotoHigher | C11: AV200 | D11: Canon 5D Mark II or 7D | E11: ? | F11: 2 | G11: 590 | H11: 975 | I11: www.photohigher.co.nz
A13: 1 | B13: Tarot | C13: T-2D | D13: GoPro 3/3+ | E13: 2-4 | F13: 2 | G13: 200 | H13: 139 | I13: www.hobby-wing.com
F14: MIN: | G14: =MIN(G3:G13) -> 157 | H14: =MIN(H3:H13) -> 139 | I14: =NOW() -> 41834.849
D15: Round 1: | F15: MAX: | G15: =MAX(G4:G14) -> 1420 | H15: =MAX(H4:H14) -> 2999
D16: Incompatible with GoPro | F16: AVG: | G16: =AVERAGE(G6:G15) -> 565.25 | H16: =AVERAGE(H6:H15) -> 1111
D18: Round 2: | I18: Other Gimbal Brands:
D19: H3-3D is better | I19: Tarot
D20: Low Price | I20: Storm
I21: Airy
D22: Round 3: | I22: Walkera
D23: Trust DJI Gimbal over Arris
D25: Selected

Sheet 7. Motors
A1: Option | B1: Brand | C1: Line | D1: Model | E1: Lipo Cells | F1: KV (rpm/v) | G1: No Load Current (Amps) @10v | H1: Max Watts | I1: Max Current (Amps) | J1: Internal Resistance (ohm) | K1: Number of Poles | L1: Shaft Length (mm) | M1: Shaft Diameter (mm) | N1: Stator Diameter (mm) | O1: Body Length | P1: Mass (grams) | Q1: Recommended ESC (Amp Rating) | R1: Price (US$) | S1: Link | T1: Comments
A2: 37 | B2: Scorpion | C2: HKIII | D2: HKIII4035-330 | E2: 12 | F2: 330 | G2: 1.33 | H2: 3500 | I2: 60 | J2: 0.031 | K2: 10 | L2: 100 | M2: 5.98 | N2: 40 | O2: 68.1 | P2: 460 | Q2: 80 | R2: 199.99 | S2: www.scorpionsystem.com
B3: Scorpion | C3: HKIII | D3: HKIII4035-450 | E3: 12 | F3: 450 | G3: 1.85 | H3: 3300 | I3: 75 | J3: 0.02 | K3: 10 | L3: 100 | M3: 5.98 | N3: 40 | O3: 68.1 | P3: 460 | Q3: 100 | R3: 199.99 | S3: www.scorpionsystem.com
B4: Scorpion | C4: HKIII | D4: HKIII4035-500 | E4: 12 | F4: 500 | G4: 2.02 | H4: 4600 | I4: 84 | J4: 0.016 | K4: 10 | L4: 100 | M4: 5.98 | N4: 40 | O4: 68.1 | P4: 460 | Q4: 100 | R4: 199.99 | S4: www.scorpionsystem.com
B5: Scorpion | C5: HKIII | D5: HKIII4035-530 | E5: 12 | F5: 530 | G5: 2.15 | H5: 4400 | I5: 80 | J5: 0.015 | K5: 10 | L5: 100 | M5: 5.98 | N5: 40 | O5: 68.1 | P5: 460 | Q5: 100 | R5: 199.99 | S5: www.scorpionsystem.com
B6: Scorpion | C6: HKIII | D6: HKIII4035-560 | E6: 12 | F6: 560 | G6: 2.24 | H6: 5200 | I6: 100 | J6: 0.014 | K6: 10 | L6: 100 | M6: 5.98 | N6: 40 | O6: 68.1 | P6: 460 | Q6: 120 | R6: 199.99 | S6: www.scorpionsystem.com
B8: Scorpion | C8: M-40 Series | D8: M4010-360 | E8: 3-6 | F8: 360 | G8: 0.34 | H8: 510 | I8: 23 | J8: 0.152 | K8: 14 | L8: 36.5 | M8: 3.98 | N8: 40 | O8: 32.17 | P8: 152 | Q8: 30 | R8: 99.99 | S8: www.scorpionsystem.com | T8: High Contender | U8: 14.8v 15inX5.5in (1125g @ 7.7 Amps) | V8: 22.2v 12inX5.5in (1225g @ 8.1 Amps)
B9: Scorpion | C9: M-40 Series | D9: M4015-340 | E9: 3-8 | F9: 340 | G9: 0.47 | H9: 740 | I9: 25 | J9: 0.108 | K9: 14 | L9: 41 | M9: 3.98 | N9: 40 | O9: 37.17 | P9: 194 | Q9: 30 | R9: 109.99 | S9: www.scorpionsystem.com | T9: High contender | U9: 14.8v 14inX5.5in (1000g @ 7.96 Amps) | V9: 22.2v 12inX5.5in (1250g @ 8.56 Amps)
B11: Scorpion | C11: SII | D11: SII4020-420 | E11: 6 | F11: 420 | G11: 0.91 | H11: 1500 | I11: 70 | J11: 0.034 | K11: 14 | L11: 78.4 | M11: 5.98 | N11: 40 | O11: 46.15 | P11: 288 | Q11: 80 | R11: 139.99 | S11: www.scorpionsystem.com
B12: Scorpion | C12: SII | D12: SII4020-540 | E12: 6 | F12: 540 | G12: 1.22 | H12: 1850 | I12: 85 | J12: 0.034 | K12: 14 | L12: 78.4 | M12: 5.98 | N12: 40 | O12: 46.15 | P12: 288 | Q12: 90 | R12: 139.99 | S12: www.scorpionsystem.com
B13: Scorpion | C13: SII | D13: SII4020-630 | E13: 5 | F13: 630 | G13: 1.54 | H13: 1500 | I13: 95 | J13: 0.034 | K13: 14 | L13: 78.4 | M13: 5.98 | N13: 40 | O13: 46.15 | P13: 288 | Q13: 100 | R13: 139.99 | S13: www.scorpionsystem.com
B15: Scorpion | C15: SII | D15: SII4025-330 | E15: 8 | F15: 330 | G15: 0.74 | H15: 2000 | I15: 75 | J15: 0.037 | K15: 14 | L15: 85 | M15: 5.98 | N15: 40 | O15: 54.1 | P15: 353 | Q15: 80 | R15: 149.99 | S15: www.scorpionsystem.com
B16: Scorpion | C16: SII | D16: SII4025-440 | E16: 7 | F16: 440 | G16: 1.1 | H16: 2000 | I16: 85 | J16: 0.025 | K16: 14 | L16: 85 | M16: 5.98 | N16: 40 | O16: 54.1 | P16: 353 | Q16: 90 | R16: 149.99 | S16: www.scorpionsystem.com
B17: Scorpion | C17: SII | D17: SII4025-520 | E17: 6 | F17: 520 | G17: 1.4 | H17: 2000 | I17: 100 | J17: 0.016 | K17: 14 | L17: 85 | M17: 5.98 | N17: 40 | O17: 54.1 | P17: 353 | Q17: 110 | R17: 149.99 | S17: www.scorpionsystem.com
B19: Scorpion | C19: SII | D19: SII4035-250 | E19: 12 | F19: 250 | G19: 0.69 | H19: 2700 | I19: 65 | J19: 0.037 | K19: 14 | L19: 95 | M19: 7.98 | N19: 40 | O19: 64.9 | P19: 450 | Q19: 70 | R19: 169.99 | S19: www.scorpionsystem.com
B20: Scorpion | C20: SII | D20: SII4035-330 | E20: 11 | F20: 330 | G20: 1.41 | H20: 2400 | I20: 65 | J20: 0.031 | K20: 10 | L20: 95 | M20: 7.98 | N20: 40 | O20: 64.9 | P20: 435 | Q20: 70 | R20: 169.99 | S20: www.scorpionsystem.com
B21: Scorpion | C21: SII | D21: SII4035-380 | E21: 11 | F21: 380 | G21: 1.52 | H21: 2600 | I21: 70 | J21: 0.025 | K21: 10 | L21: 95 | M21: 7.98 | N21: 40 | O21: 64.9 | P21: 435 | Q21: 80 | R21: 169.99 | S21: www.scorpionsystem.com
B22: Tiger | C22: Antigravity | D22: AG4014-330 | E22: 4-8 | F22: 330 | G22: 1.1 | H22: 750 | I22: 25 | J22: 0.085 | K22: 18 | L22: 14 | M22: 4 | N22: 44.8 | O22: 34.5 | P22: 149 | Q22: 30 | R22: 194.9 | S22: www.rctigermotor.com
A24: 1 | B24: Tiger | C24: Power | D24: U3-700 | E24: 3-4 | F24: 700 | G24: 0.5 | H24: 500 | I24: 25 | J24: 0.05 | K24: 14 | L24: ? | M24: 4 | N24: 41.8 | O24: 30.75 | P24: 97 | Q24: 30 | R24: 109.9 | S24: http://www.diyquadcopters.com | T24: High Contender | U24: 14.8v 13inX4.4in (1120g @ 65%throttle) | V24: 6100rpm at 8.48 g/W
B25: Tiger | C25: Power | D25: U5-400 | E25: 3-8 | F25: 400 | G25: 0.3 | H25: 850 | I25: 30 | J25: 0.116 | K25: 14 | L25: ? | M25: 4 | N25: 42.5 | O25: 37.5 | P25: 156 | Q25: 35 | R25: 125.9 | S25: www.rctigermotor.com | T25: Too Powerful | U25: 22.2v 14inX4.8in (1200g @ 65%throttle)
B26: Tiger | C26: Power | D26: U7-420 | E26: 3-8 | F26: 420 | G26: 1.1 | H26: 1180 | I26: 40 | J26: 0.033 | K26: 14 | L26: ? | M26: 4 | N26: 60.7 | O26: 39.5 | P26: 255 | Q26: 40 | R26: 149.9 | S26: www.rctigermotor.com
B27: Tiger | C27: Power | D27: U7-490 | E27: 3-8 | F27: 490 | G27: 1.1 | H27: 1300 | I27: 44 | J27: 0.021 | K27: 14 | L27: ? | M27: 4 | N27: 60.7 | O27: 39.5 | P27: 258 | Q27: 44 | R27: 149.9 | S27: www.rctigermotor.com
B29: Tiger | C29: Professional | D29: MT4006-740 | E29: 3-4 | F29: 740 | G29: 0.5 | H29: 500 | I29: 27 | J29: 0.136 | K29: 24 | L29: 6 | M29: 4 | N29: 40 | O29: 24 | P29: 92 | Q29: 30 | R29: 82.9 | S29: www.rctigermotor.com | T29: Too Weak
B30: Tiger | C30: T-Motor | D30: MN3510-360 | E30: 3-6 | F30: 360 | G30: 0.4 | H30: 330 | I30: 15 | J30: 0.188 | K30: 14 | L30: 10 | M30: 4 | N30: 35 | O30: 28.5 | P30: 97 | Q30: 20 | R30: 79.9 | S30: www.rctigermotor.com
B31: Tiger | C31: T-Motor | D31: MN3510-630 | E31: 3-4 | F31: 630 | G31: 0.5 | H31: 495 | I31: 22 | J31: 0.065 | K31: 14 | L31: 10 | M31: 4 | N31: 35 | O31: 28.5 | P31: 97 | Q31: 25 | R31: 79.9 | S31: www.rctigermotor.com
B32: Tiger | C32: T-Motor | D32: MN3510-700 | E32: 3-4 | F32: 700 | G32: 0.5 | H32: 555 | I32: 25 | J32: 0.05 | K32: 14 | L32: 10 | M32: 4 | N32: 35 | O32: 28.5 | P32: 97 | Q32: 25 | R32: 79.9 | S32: www.rctigermotor.com | T32: Very simliar to U3 but older version | U32: 14.8v 13inX4.4in (1120g @ 65%throttle) | V32: 6100rpm at 8.48
B34: Tiger | C34: T-Motor | D34: MN3515-400 | E34: 4-8 | F34: 400 | G34: 0.3 | H34: 900 | I34: 30 | J34: 0.116 | K34: 14 | L34: 15 | M34: 4 | N34: 35 | O34: 34.5 | P34: 183 | Q34: 30 | R34: 96.9 | S34: www.rctigermotor.com
B35: Tiger | C35: T-Motor | D35: MN3520-400 | E35: 4-8 | F35: 400 | G35: 1.2 | H35: 1140 | I35: 38 | J35: 0.082 | K35: 14 | L35: 20 | M35: 4 | N35: 35 | O35: 42 | P35: 194 | Q35: 40 | R35: 109.9 | S35: www.rctigermotor.com
B37: Tiger | C37: T-Motor | D37: MN4010-370 | E37: 4-8 | F37: 370 | G37: 0.8 | H37: 450 | I37: 20 | J37: 0.098 | K37: 24 | L37: 10 | M37: 4 | N37: 40 | O37: 30.5 | P37: 112 | Q37: 20 | R37: 86.9 | S37: www.rctigermotor.com
B38: Tiger | C38: T-Motor | D38: MN4010-475 | E38: 4-8 | F38: 475 | G38: 0.8 | H38: 540 | I38: 30 | J38: 0.098 | K38: 24 | L38: 10 | M38: 4 | N38: 40 | O38: 30.5 | P38: 110 | Q38: 30 | R38: 86.9 | S38: www.rctigermotor.com | T38: 4S and 6S Data | U38: 14.8v 16inX5.4in (1060g @ 65%throttle) | V38: 22.2v 13inX4.4in (1070g @ 65%throttle) | W38: 3800 at 9.72g/W, 6300 at 7.23 g/W
B39: Tiger | C39: T-Motor | D39: MN4010-580 | E39: 4-8 | F39: 580 | G39: 1.3 | H39: 575 | I39: 31 | J39: 0.042 | K39: 24 | L39: 10 | M39: 4 | N39: 40 | O39: 30.5 | P39: 112 | Q39: 40 | R39: 86.9 | S39: www.rctigermotor.com | T39: Only data for 4S | U39: 14.8v 14inX4.8in (1000g @ 65%throttle) | V39: 14.8v 15inX5in (1190g @ 65%throttle) | W39: 5000rpm at 7.87 g/W, 4800rpm at 8.10g/W
B41: Tiger | C41: T-Motor | D41: MN4012-340 | E41: 4-8 | F41: 340 | G41: 0.9 | H41: 660 | I41: 22 | J41: 0.133 | K41: 24 | L41: 12 | M41: 4 | N41: 40 | O41: 32.5 | P41: 131 | Q41: 30 | R41: 92.9 | S41: www.rctigermotor.com | T41: Only data for 6S | U41: 22.2v 15inX5in (1110g @ 65%throttle) | V41: 4400rpm at 9.02g/W
B42: Tiger | C42: T-Motor | D42: MN4012-400 | E42: 4-8 | F42: 400 | G42: 1 | H42: 750 | I42: 25 | J42: 0.075 | K42: 24 | L42: 12 | M42: 4 | N42: 40 | O42: 32.5 | P42: 128 | Q42: 30 | R42: 92.9 | S42: www.rctigermotor.com | T42: Too Powerful | U42: 22.2v 14inX4.8in (1150g @ 65%throttle) | V42: 5300rpm at 7.93g/W
B43: Tiger | C43: T-Motor | D43: MN4012-480 | E43: 4-8 | F43: 480 | G43: 1.3 | H43: 870 | I43: 29 | J43: 0.057 | K43: 24 | L43: 12 | M43: 4 | N43: 40 | O43: 32.5 | P43: 134 | Q43: 30 | R43: 92.9 | S43: www.rctigermotor.com
B45: Tiger | C45: T-Motor | D45: MN4014-330 | E45: 4-8 | F45: 330 | G45: 1.1 | H45: 750 | I45: 25 | J45: 0.085 | K45: 24 | L45: 14 | M45: 4 | N45: 40 | O45: 34.5 | P45: 149 | Q45: 25 | R45: 96.9 | S45: www.rctigermotor.com | T45: Too Powerful | U45: 22.2v 15inX5in (1150g @ 65%throttle) | V45: 4600rpm at 9.13g/W
B46: Tiger | C46: T-Motor | D46: MN4014-400 | E46: 4-8 | F46: 400 | G46: 1.3 | H46: 900 | I46: 30 | J46: 0.067 | K46: 24 | L46: 14 | M46: 4 | N46: 40 | O46: 34.5 | P46: 150 | Q46: 30 | R46: 96.9 | S46: www.rctigermotor.com
B48: Tiger | C48: T-Motor | D48: MN4120-400 | E48: 4-8 | F48: 400 | G48: 1.12 | H48: 1050 | I48: 47 | J48: 0.03 | K48: 14 | L48: 20 | M48: 4 | N48: 41 | O48: 42 | P48: 253 | Q48: 50 | R48: 119.9 | S48: www.rctigermotor.com
A49: 1 | B49: Tiger | C49: T-Motor | D49: MN4120-465 | E49: 4-8 | F49: 465 | G49: 1.4 | H49: 1200 | I49: 50 | J49: 0.024 | K49: 14 | L49: 20 | M49: 4 | N49: 41 | O49: 42 | P49: 253 | Q49: 50 | R49: 119.9 | S49: www.rctigermotor.com
E50: Min: | F50: =MIN(F48:F49,F45:F46,F41:F43,F37:F39,F34:F35,F25:F27,F11:F13,F8:F9) -> 330 | G50: =MIN(G48:G49,G45:G46,G41:G43,G37:G39,G34:G35,G25:G27,G11:G13,G8:G9) -> 0.3 | H50: =MIN(H48:H49,H45:H46,H41:H43,H37:H39,H34:H35,H25:H27,H11:H13,H8:H9) -> 450 | I50: =MIN(I48:I49,I45:I46,I41:I43,I37:I39,I34:I35,I25:I27,I11:I13,I8:I9) -> 20 | J50: =MIN(J48:J49,J45:J46,J41:J43,J37:J39,J34:J35,J25:J27,J11:J13,J8:J9) -> 0.021 | K50: =MIN(K48:K49,K45:K46,K41:K43,K37:K39,K34:K35,K25:K27,K11:K13,K8:K9) -> 14 | L50: =MIN(L48:L49,L45:L46,L41:L43,L37:L39,L34:L35,L25:L27,L11:L13,L8:L9) -> 10 | M50: =MIN(M48:M49,M45:M46,M41:M43,M37:M39,M34:M35,M25:M27,M11:M13,M8:M9) -> 3.98 | ... R50: =MIN(R48:R49,R45:R46,R41:R43,R37:R39,R34:R35,R25:R27,R11:R13,R8:R9) -> 86.9 | S50: =NOW() -> 41834.849
C51: Round 1: | E51: Max: | F51: =MAX(F48:F49,F45:F46,F41:F43,F37:F39,F34:F35,F25:F27,F11:F13,F8:F9) -> 630 | G51: =MAX(G48:G49,G45:G46,G41:G43,G37:G39,G34:G35,G25:G27,G11:G13,G8:G9) -> 1.54 | H51: =MAX(H48:H49,H45:H46,H41:H43,H37:H39,H34:H35,H25:H27,H11:H13,H8:H9) -> 1850 | I51: =MAX(I48:I49,I45:I46,I41:I43,I37:I39,I34:I35,I25:I27,I11:I13,I8:I9) -> 95 | J51: =MAX(J48:J49,J45:J46,J41:J43,J37:J39,J34:J35,J25:J27,J11:J13,J8:J9) -> 0.152 | K51: =MAX(K48:K49,K45:K46,K41:K43,K37:K39,K34:K35,K25:K27,K11:K13,K8:K9) -> 24 | L51: =MAX(L48:L49,L45:L46,L41:L43,L37:L39,L34:L35,L25:L27,L11:L13,L8:L9) -> 78.4 | M51: =MAX(M48:M49,M45:M46,M41:M43,M37:M39,M34:M35,M25:M27,M11:M13,M8:M9) -> 5.98 | ... R51: =MAX(R48:R49,R45:R46,R41:R43,R37:R39,R34:R35,R25:R27,R11:R13,R8:R9) -> 149.9
...

Sheet 8. ESCs
A1: Electronic Speed Controllers (ESC)
A2: Option | B2: Brand | C2: MODEL | D2: method | E2: Continuous Current (A) | F2: Burst Current (A) | G2: Lipo Cells | H2: MASS (g) | I2: Simon K Firmware? | J2: PRICE | K2: Link
B3: Hobbywing | C3: FlyFun 30 | D3: BEC | E3: 30 | F3: 40 | G3: 2-4 | H3: 25 | J3: 19.99 | K3: http://www.hobby-wing.com
B4: Hobbywing | C4: FlyFun 40 | D4: BEC | E4: 40 | F4: 60 | G4: 2-6 | H4: 35 | J4: 28.5 | K4: http://www.hobby-wing.com
B5: Hobbywing | C5: Platinum 30 | D5: OPTO | E5: 30 | F5: 45 | G5: 2-6 | H5: 31.6 | J5: 26 | K5: http://www.hobby-wing.com/hobby-wing-platinum-30a-pro.html
B7: Maytech | C7: MT 30 | D7: OPTO | E7: 30 | F7: 40 | G7: 2-4 | H7: 27 | J7: 30 | K7: http://www.rc-drones.com/Maytech-MT30A-ESC.php
B8: Maytech | C8: MT 35 | D8: OPTO | E8: 35 | F8: 50 | G8: 2-4 | H8: 27 | J8: 30 | K8: http://www.rc-drones.com/Maytech-MT35A-esc.php
B9: Maytech | C9: MT 40 | D9: OPTO | E9: 40 | F9: 60 | G9: 2-6 | H9: 35 | J9: 37 | K9: http://www.rc-drones.com/rcd-mt40a-opto-v1-esc.php
B10: Maytech | C10: MT 60 | D10: OPTO | E10: 60 | F10: 80 | G10: 2-6 | H10: 51 | J10: 60 | K10: http://www.rc-drones.com/rcd-mt60a-opto-v1-esc.php
B12: T-Motor | C12: T 30 | D12: BEC | E12: 30 | F12: 40 | G12: 2-4 | H12: 25 | J12: 28.99 | K12: http://www.rctigermotor.com/html/2013/esc_0916/83.html
A13: 1 | B13: T-Motor | C13: S 35A | D13: NO-BEC | E13: 35 | F13: 45 | G13: 2-6 | H13: 30 | I13: YES | J13: 29.99 | K13: http://www.diyquadcopters.com
B14: T-Motor | C14: T 30 Pro | D14: NO-BEC | E14: 30 | F14: 40 | G14: 2-6 | H14: 31 | J14: 49.99 | K14: http://www.rctigermotor.com/html/2013/esc_0916/87.html
B15: T-Motor | C15: T 40 | D15: BEC | E15: 40 | F15: 60 | G15: 2-6 | H15: 35 | J15: 45.99 | K15: http://www.rctigermotor.com/html/2013/esc_0916/84.html
B16: T-Motor | C16: T 40 Pro | D16: ? | E16: 40 | F16: 60 | G16: 2-6 | H16: 29 | J16: 55.99 | K16: http://www.rctigermotor.com/html/2013/esc_0916/88.html
B17: T-Motor | C17: S 45A | D17: NO-BEC | E17: 45 | F17: 55 | G17: 2-6 | H17: 45 | I17: YES | J17: 39.99 | K17: http://www.diyquadcopters.com/T-Motor-45a-ESC-with-simonK-factory-firmware_p_154.html
B18: T-Motor | C18: T 60 | D18: BEC | E18: 60 | F18: 80 | G18: 2-6 | H18: 60 | J18: 59.99 | K18: http://www.rctigermotor.com/html/2013/esc_0916/85.html
B20: Turnigy | C20: Multistar 20 | D20: BEC Switching | E20: 20 | F20: ? | G20: 2-4 | H20: 25 | J20: 10.55 | K20: http://www.hobbyking.com/hobbyking/store/__25364__Turnigy_Multistar_20_Amp_Multi_rotor_Brushless_ESC_2_4S.html
B21: Turnigy | C21: Multistar 30 | D21: OPTO | E21: 30 | F21: ? | G21: 2-4 | H21: 32 | J21: 11.29 | K21: http://www.hobbyking.com/hobbyking/store/__27776__Turnigy_Multistar_30_Amp_Multi_rotor_Brushless_ESC_2_4S_OPTO_.html
B22: Turnigy | C22: Multistar 45 | D22: OPTO | E22: 45 | F22: ? | G22: 2-6 | H22: 63 | J22: 19.46 | K22: http://www.hobbyking.com/hobbyking/store/__27777__Turnigy_Multistar_45_Amp_Multi_rotor_Brushless_ESC_2_6S_OPTO_.html
B23: Turnigy | C23: Multistar 60 | D23: OPTO | E23: 60 | F23: ? | G23: 2-6 | H23: 62 | J23: 22.12 | K23: http://www.hobbyking.com/hobbyking/store/__45503__Turnigy_Multistar_60_Amp_Multi_rotor_Brushless_ESC_2_6S_OPTO_.html
B25: Turnigy | C25: Plush 25 | D25: BEC Linear | E25: 25 | F25: 35 | G25: 2-4 | H25: 22 | J25: 13.44 | K25: http://www.hobbyking.com/hobbyking/store/uh_viewitem.asp?idproduct=2163&aff=586251
B26: Turnigy | C26: Plush 30 | D26: BEC Linear | E26: 30 | F26: 40 | G26: 2-4 | H26: 25 | J26: 13.13 | K26: http://www.hobbyking.com/hobbyking/store/uh_viewitem.asp?idproduct=2164&aff=586251
B27: Turnigy | C27: Plush 40 | D27: BEC Linear | E27: 40 | F27: 55 | G27: 2-6 | H27: 33 | J27: 21.99 | K27: http://www.hobbyking.com/hobbyking/store/uh_viewitem.asp?idproduct=2165&aff=586251
B28: Turnigy | C28: Plush 60 | D28: BEC Switching | E28: 60 | F28: 80 | G28: 2-6 | H28: 60 | J28: 34.88 | K28: http://www.hobbyking.com/hobbyking/store/uh_viewitem.asp?idproduct=2166&aff=586251
B30: Turnigy | C30: Super Brain 45 | D30: BEC Linear | E30: 45 | F30: 65 | G30: 2-6 | H30: 40 | J30: 39.19 | K30: http://www.hobbyking.com/hobbyking/store/__24889__Turnigy_Super_Brain_45A_6s_Brushless_ESC.html
B31: Turnigy | C31: Super Brain 60 | D31: BEC Switching | E31: 60 | F31: 70 | G31: 2-6 | H31: 50 | J31: 49.99 | K31: http://www.hobbyking.com/hobbyking/store/__10942__Turnigy_Super_Brain_60A_Brushless_ESC.html
A32: 1 | B32: Turnigy | C32: Super Brain 80 | D32: BEC Switching | E32: 80 | F32: 90 | G32: 2-6 | H32: 52 | J32: 69.99 | K32: http://www.hobbyking.com/hobbyking/store/__10943__Turnigy_Super_Brain_80A_Brushless_ESC.html
C34: Round 1:
C35: Skipped
C37: Round 2:
C38: All Motors < 50A
C40: Round 3:
C41: Not Turnigy
C42: All Motors < 40A
C44: Round 4:
C45: Price
C46: Added
C48: Round 5:
C49: Selected

Sheet 9. Batteries
A1: Batteries
A2: Option | B2: Brand | C2: Model | D2: Lipo Cells | E2: Voltage | F2: mAh | G2: Max Continuous Current (Amps) | H2: Peak Current | I2: Length (mm) | J2: Width (mm) | K2: Height (mm) | L2: Mass (grams) | M2: Price (US$) | N2: mAh/mm^3 | O2: $/mAh | P2: mAh/g | Q2: Link
A3: 19 | B3: ADC | C3: 10,000mAh 6S 25C | D3: 6 | E3: 22.2 | F3: 10000 | G3: 40 | H3: ? | I3: 165 | J3: 62 | K3: 55 | L3: 1368 | M3: 279 | N3: =F3/(I3*J3*K3) -> 0.017773038 | O3: =M3/F3 -> 0.0279 | P3: =F3/L3 -> 7.3099415 | Q3: http://www.hobby-wing.com/roc-6s-10000mah-25c-polymer-lithium-lipo-battery.html
B4: ADC | C4: 5000mAh 6S 40C | D4: 6 | E4: 22.2 | F4: 5000 | G4: 40 | H4: ? | I4: 145 | J4: 50 | K4: 50 | L4: 790 | M4: 189 | N4: =F4/(I4*J4*K4) -> 0.013793103 | O4: =M4/F4 -> 0.0378 | P4: =F4/L4 -> 6.3291139 | Q4: http://www.hobby-wing.com/roc-6s-22v-5000mah-40c-battery.html
B6: E-flite | C6: 5000mAh 5S 30C | D6: 5 | E6: 18.5 | F6: 5000 | G6: 30 | H6: ? | I6: 164 | J6: 43.2 | K6: 45.7 | L6: 672 | M6: 149.99 | N6: =F6/(I6*J6*K6) -> 0.015442806 | O6: =M6/F6 -> 0.029998 | P6: =F6/L6 -> 7.4404762 | Q6: http://www.horizonhobby.com/products/5000mah-5s-18-5v-30c-lipo-10awg-ec5-EFLB50005S30
B7: E-flite | C7: 5000mAh 6S 30C | D7: 6 | E7: 22.2 | F7: 5000 | G7: 30 | H7: ? | I7: 164 | J7: 54.6 | K7: 43.2 | L7: 808 | M7: 179.99 | N7: =F7/(I7*J7*K7) -> 0.012925572 | O7: =M7/F7 -> 0.035998 | P7: =F7/L7 -> 6.1881188 | Q7: http://www.horizonhobby.com/products/5000mah-6s-22-2v-30c-lipo-10awg-ec5-EFLB50006S30#t2
B8: E-flite | C8: 5000mAh 6S 50C | D8: 6 | E8: 22.2 | F8: 5000 | G8: 50 | H8: ? | I8: 134 | J8: 64 | K8: 45 | L8: 834 | M8: 239.99 | N8: =F8/(I8*J8*K8) -> 0.012956053 | O8: =M8/F8 -> 0.047998 | P8: =F8/L8 -> 5.9952038 | Q8: http://www.horizonhobby.com/products/5000mah-6s-22-2v-50c-lipo-10awg-ec5-EFLB50006S50#t2
B10: Hyperion | C10: G3 4S 5000 35C | D10: 4 | E10: 14.8 | F10: 5000 | G10: 35 | H10: 65 | I10: 158.8 | J10: 45 | K10: 37.6 | L10: 545 | M10: 120 | N10: =F10/(I10*J10*K10) -> 0.018608833 | O10: =M10/F10 -> 0.024 | P10: =F10/L10 -> 9.1743119 | Q10: http://rc-drones.com/hyp-G3-5000-4s.php
B11: Hyperion | C11: G3 4S 5400 35C | D11: 4 | E11: 14.8 | F11: 5400 | G11: 35 | H11: 65 | I11: 158.5 | J11: 46.8 | K11: 40.2 | L11: 594 | M11: 127.99 | N11: =F11/(I11*J11*K11) -> 0.018108922 | O11: =M11/F11 -> 0.023701852 | P11: =F11/L11 -> 9.0909091 | Q11: http://rc-drones.com/hyp-g3-vx5400-4s.php
B12: Hyperion | C12: G3 6S 5000 35C | D12: 6 | E12: 22.2 | F12: 5000 | G12: 35 | H12: 65 | I12: 158.5 | J12: 45 | K12: 55.8 | L12: 849 | M12: 163 | N12: =F12/(I12*J12*K12) -> 0.012563019 | O12: =M12/F12 -> 0.0326 | P12: =F12/L12 -> 5.8892815 | Q12: http://www.rc-drones.com/hyp-G3-VX-5000mAh-6S-35C.php
B13: Hyperion | C13: G3 6S 5400 35C | D13: 6 | E13: 22.2 | F13: 5400 | G13: 35 | H13: 65 | I13: 158.5 | J13: 46.8 | K13: 60.5 | L13: 920 | M13: 189 | N13: =F13/(I13*J13*K13) -> 0.012032705 | O13: =M13/F13 -> 0.035 | P13: =F13/L13 -> 5.8695652 | Q13: http://www.rc-drones.com/hyp-g36s-5400.php
B15: Lumenier | C15: 5200mAh 4S 35C | D15: 4 | E15: 14.8 | F15: 5200 | G15: 35 | H15: 70 | I15: 152 | J15: 48 | K15: 32 | L15: 505 | M15: 74.99 | N15: =F15/(I15*J15*K15) -> 0.022272478 | O15: =M15/F15 -> 0.014421154 | P15: =F15/L15 -> 10.29703 | Q15: http://www.getfpv.com/batteries/flight-packs/lumenier-5200mah-4s-35c-lipo-battery.html
B16: ThunderPower | C16: 5000mAh 6S 70C | D16: 6 | E16: 22.2 | F16: 5000 | G16: 70 | H16: 140 | I16: 156 | J16: 46 | K16: 49 | L16: 796 | M16: 246.99 | N16: =F16/(I16*J16*K16) -> 0.014219735 | O16: =M16/F16 -> 0.049398 | P16: =F16/L16 -> 6.281407 | Q16: http://www.horizonhobby.com/products/5000mah-6s-22-2v-g8-pro-force-70c-lipo-THP50006SPF70#t2
B18: Turnigy | C18: A-SPEC 5000mAh 4S 65C | D18: 4 | E18: 14.8 | F18: 5000 | G18: 65 | H18: 130 | I18: 156 | J18: 46 | K18: 35 | L18: 537 | M18: 90.66 | N18: =F18/(I18*J18*K18) -> 0.019907629 | O18: =M18/F18 -> 0.018132 | P18: =F18/L18 -> 9.310987 | Q18: http://www.hobbyking.com/hobbyking/store/__45143__Turnigy_nano_tech_A_SPEC_G2_5000mah_4S_65_130C_Lipo_Pack.html
B19: Turnigy | C19: A-SPEC 5000mAh 6S 65C | D19: 6 | E19: 22.2 | F19: 5000 | G19: 65 | H19: 130 | I19: 156 | J19: 46 | K19: 51 | L19: 786 | M19: 148.05 | N19: =F19/(I19*J19*K19) -> 0.013662098 | O19: =M19/F19 -> 0.02961 | P19: =F19/L19 -> 6.3613232 | Q19: http://www.hobbyking.com/hobbyking/store/__45145__Turnigy_nano_tech_A_SPEC_G2_5000mah_6S_65_130C_Lipo_Pack.html
B20: Turnigy | C20: A-SPEC 5000mAh 6S 65C | D20: 6 | E20: 22.2 | F20: 5000 | G20: 65 | H20: 130 | I20: 153 | J20: 54 | K20: 49 | L20: 840 | M20: 129.99 | N20: =F20/(I20*J20*K20) -> 0.012350619 | O20: =M20/F20 -> 0.025998 | P20: =F20/L20 -> 5.952381 | Q20: http://www.hobbyking.com/hobbyking/store/__45145__Turnigy_nano_tech_A_SPEC_G2_5000mah_6S_65_130C_Lipo_Pack.html
B21: Turnigy | C21: A-SPEC G2 5000mAh 6S 65C | D21: 6 | E21: 22.2 | F21: 5000 | G21: 65 | H21: 130 | I21: 156 | J21: 51 | K21: 46 | L21: 786 | M21: 148.05 | N21: =F21/(I21*J21*K21) -> 0.013662098 | O21: =M21/F21 -> 0.02961 | P21: =F21/L21 -> 6.3613232 | Q21: http://www.hobbyking.com/hobbyking/store/__45145__Turnigy_nano_tech_A_SPEC_G2_5000mah_6S_65_130C_Lipo_Pack.html
A23: 1 | B23: Xaircraft | C23: 5800mAh 4S 35C | D23: 4 | E23: 14.8 | F23: 5800 | G23: 35 | H23: ? | I23: =6*25.4 -> 152.4 | J23: =2.1*25.4 -> 53.34 | K23: =1.4*25.4 -> 35.56 | L23: 585 | M23: 90 | N23: =F23/(I23*J23*K23) -> 0.020064496 | O23: =M23/F23 -> 0.015517241 | P23: =F23/L23 -> 9.9145299 | Q23: http://xaircraftamerica.com
B24: Turnigy | C24: nano-tech 5000mAh 4S 65C | D24: 4 | E24: 14.8 | F24: 5000 | G24: 65 | H24: 130 | I24: 153 | J24: 49 | K24: 37 | L24: 576 | M24: 76.59 | N24: =F24/(I24*J24*K24) -> 0.018025228 | O24: =M24/F24 -> 0.015318 | P24: =F24/L24 -> 8.6805556 | Q24: http://www.hobbyking.com
B25: Turnigy | C25: nano-tech 5000mAh 5S 65C | D25: 5 | E25: 18.5 | F25: 5000 | G25: 65 | H25: 130 | I25: 154 | J25: 46 | K25: 49 | L25: 712 | M25: 88.85 | N25: =F25/(I25*J25*K25) -> 0.014404407 | O25: =M25/F25 -> 0.01777 | P25: =F25/L25 -> 7.0224719 | Q25: http://www.hobbyking.com/hobbyking/store/__19155__Turnigy_nano_tech_5000mah_5S_65_130C_Lipo_Pack.html
A26: 1 | B26: Turnigy | C26: nano-tech 5000mAh 6S 65C | D26: 6 | E26: 22.2 | F26: 5000 | G26: 65 | H26: 130 | I26: 153 | J26: 49 | K26: 55 | L26: 844 | M26: 116.7 | N26: =F26/(I26*J26*K26) -> 0.012126063 | O26: =M26/F26 -> 0.02334 | P26: =F26/L26 -> 5.9241706 | Q26: http://www.hobbyking.com/hobbyking/store/__19156__Turnigy_nano_tech_5000mah_6S_65_130C_Lipo_Pack.html
C27: Min: | D27: =MIN(D3:D26) -> 4 | E27: =MIN(E3:E26) -> 14.8 | F27: =MIN(F3:F26) -> 5000 | G27: =MIN(G3:G26) -> 30 | H27: =MIN(H3:H26) -> 65 | I27: =MIN(I3:I26) -> 134 | J27: =MIN(J3:J26) -> 43.2 | K27: =MIN(K3:K26) -> 32 | L27: =MIN(L3:L26) -> 505 | M27: =AVERAGE(M3:M26) -> 149.93842
C28: Max: | D28: =MAX(D3:D26) -> 6 | E28: =MAX(E3:E26) -> 22.2 | F28: =MAX(F3:F26) -> 10000 | G28: =MAX(G3:G26) -> 70 | H28: =MAX(H3:H26) -> 140 | I28: =MAX(I3:I26) -> 165 | J28: =MAX(J3:J26) -> 64 | K28: =MAX(K3:K26) -> 60.5 | ... M28: =MAX(M3:M26) -> 279
C29: Avg: | D29: =AVERAGE(D3:D26) -> 5.2631579 | E29: =AVERAGE(E3:E26) -> 19.473684 | F29: =AVERAGE(F3:F26) -> 5357.8947 | G29: =AVERAGE(G3:G26) -> 48.684211 | H29: =AVERAGE(H3:H26) -> 106.15385 | I29: =AVERAGE(I3:I26) -> 155.14211 | J29: =AVERAGE(J3:J26) -> 49.775789 | K29: =AVERAGE(K3:K26) -> 45.871579 | ... M29: =AVERAGE(M3:M26) -> 149.93842
C30: Round 1:
C31: Skipped | Q31: Other Battery Brands to Consider:
Q32: Storm | R32: helipal.com
C33: Round 2: | Q33: Align
C34: > $0.03 per mAh | Q34: Ace
C36: Round 3:
C37: < 7 mAh/g
C39: Round 4:
C40: Remove 5S Batteries
C41: Added
C43: Round 5:
C44: 5400 < mAh < 7000
C45: Selected

Sheet 10. Propellers
A1: Propellers
A2: Option | B2: Brand | C2: Line | D2: Model | F2: Folding? | G2: Diameter (in) | H2: Pitch (in/in) | I2: Material | J2: Mass (grams) | K2: QTY | L2: Price (US$) | M2: $/Prop | N2: Link
B3: APC | C3: APC Prop | D3: APC 12x5.5 | F3: N | G3: 12 | H3: 5.5 | I3: P | J3: 0 | K3: 1 | L3: 4 | M3: =L3/K3 -> 4 | N3: http://www.rc-drones.com
B4: DJI | C4: DJI Folding | D4: DJI 15x5.2 | F4: Y | G4: 15 | H4: 5.2 | I4: ? | J4: 13 | K4: 2 | L4: 69 | M4: =L4/K4 -> 34.5 | N4: http://www.hobby-wing.com
B5: DJI | C5: DJI Folding | D5: DJI 15x5.2 | E5: Folding | F5: Y | G5: 15 | H5: 5.2 | I5: PC | J5: 13 | K5: 2 | L5: 45 | M5: =L5/K5 -> 22.5 | N5: http://www.hobby-wing.com
B7: GemFan | C7: Hobby | D7: GF 14x7 | E7: 6mm | F7: N | G7: 14 | H7: 7 | I7: CF | J7: 0 | K7: 2 | L7: 36 | M7: =L7/K7 -> 18 | N7: http://www.rc-drones.com
B8: Gemfan | C8: T-Motor | D8: GF 11x5.5 | E8: T-Style | F8: N | G8: 11 | H8: 5.5 | I8: CF | J8: 0 | K8: 2 | L8: 19 | M8: =L8/K8 -> 9.5 | N8: http://www.diyquadcopters.com
A9: 1 | B9: Gemfan | C9: T-Motor | D9: GF 12x5.5 | E9: T-Style | F9: N | G9: 12 | H9: 5.5 | I9: CF | J9: 15 | K9: 2 | L9: 20 | M9: =L9/K9 -> 10 | N9: http://www.diyquadcopters.com
A10: 2 | B10: Gemfan | C10: T-Motor | D10: GF 13x5.5 | E10: T-Style | F10: N | G10: 13 | H10: 5.5 | I10: CF | J10: 15 | K10: 2 | L10: 22 | M10: =L10/K10 -> 11 | N10: http://www.diyquadcopters.com
A11: 3 | B11: Gemfan | C11: T-Motor | D11: GF 14x5.5 | E11: T-Style | F11: N | G11: 14 | H11: 5.5 | I11: CF | J11: 15 | K11: 2 | L11: 24 | M11: =L11/K11 -> 12 | N11: http://www.diyquadcopters.com
A12: 4 | B12: Gemfan | C12: T-Motor | D12: GF 15x5.5 | E12: T-Style | F12: N | G12: 15 | H12: 5.5 | I12: CF | J12: 15 | K12: 2 | L12: 26 | M12: =L12/K12 -> 13 | N12: http://www.diyquadcopters.com
A13: 5 | B13: GemFan | C13: DJI S800 Style | D13: GF 15x5.5 | E13: T-Style | F13: N | G13: 15 | H13: 5.5 | I13: CF | J13: 16.4 | K13: 2 | L13: 40 | M13: =L13/K13 -> 20 | N13: http://www.rc-drones.com
A14: 6 | B14: GemFan | C14: Scoop Style | D14: GF 15x7.5 | E14: T-Style | F14: N | G14: 15 | H14: 7.5 | I14: CF | J14: 12.5 | K14: 2 | L14: 40 | M14: =L14/K14 -> 20 | N14: http://www.rc-drones.com
A15: 7 | B15: Gemfan | C15: T-Motor | D15: GF 15x5.5 | E15: T-Style | F15: N | G15: 15 | H15: 5.5 | I15: CF | J15: 0 | K15: 2 | L15: 40 | M15: =L15/K15 -> 20 | N15: http://www.rc-drones.com
A16: 8 | B16: GemFan | C16: Paddle Style | D16: GF 15.5x5.5 | E16: T-Style | F16: N | G16: 15.5 | H16: 5.5 | I16: CF | J16: 20 | K16: 2 | L16: 40 | M16: =L16/K16 -> 20 | N16: http://www.rc-drones.com
B17: GemFan | C17: CF Folding Prop | D17: GF ? | F17: Y | G17: ? | H17: ? | I17: CF | J17: 0 | K17: 1 | L17: 20 | M17: =L17/K17 -> 20 | N17: http://www.rc-drones.com
B19: Graupner | C19: E-Prop | D19: Gr 11x5 | E19: 8mm | F19: N | G19: 11 | H19: 5 | I19: CF | J19: 0 | K19: 1 | L19: 12 | M19: =L19/K19 -> 12 | N19: http://www.rc-drones.com
B20: Graupner | C20: E-Prop | D20: Gr 14x8 | E20: 8mm | F20: N | G20: 14 | H20: 8 | I20: CF | J20: 0 | K20: 1 | L20: 18 | M20: =L20/K20 -> 18 | N20: http://www.rc-drones.com
A22: 9 | B22: High Performance | C22: CF Prop | D22: HP 15x5.5 | E22: T Style | F22: N | G22: 15 | H22: 5.5 | I22: CF | J22: 0 | K22: 2 | L22: 35 | M22: =L22/K22 -> 17.5 | N22: http://www.hobby-wing.com
A23: 10 | B23: High Performance | C23: CF Prop | D23: HP 16x5.5 | E23: T Style | F23: N | G23: 16 | H23: 5.5 | I23: CF | J23: 0 | K23: 2 | L23: 38 | M23: =L23/K23 -> 19 | N23: http://www.hobby-wing.com
B25: Maytech | C25: MTCP1155T | D25: Mt 11x5.5 | E25: T Style | F25: N | G25: 11 | H25: 5.5 | I25: CF | J25: 0 | K25: 2 | L25: 26 | M25: =L25/K25 -> 13 | N25: http://www.rc-drones.com
A26: 11 | B26: Maytech | C26: MTCP1255T | D26: Mt 12x5.5 | E26: T Style | F26: N | G26: 12 | H26: 5.5 | I26: CF | J26: 0 | K26: 2 | L26: 30 | M26: =L26/K26 -> 15 | N26: http://www.rc-drones.com
A27: 12 | B27: Maytech | C27: MTCP1355T | D27: Mt 13x5.5 | E27: T Style | F27: N | G27: 13 | H27: 5.5 | I27: CF | J27: 0 | K27: 2 | L27: 35 | M27: =L27/K27 -> 17.5 | N27: http://www.rc-drones.com
A28: 13 | B28: Maytech | C28: MTCP1455T | D28: Mt 14x5.5 | E28: T Style | F28: N | G28: 14 | H28: 5.5 | I28: CF | J28: 0 | K28: 2 | L28: 40 | M28: =L28/K28 -> 20 | N28: http://www.rc-drones.com
B30: RC Tiger | C30: T-Motor | D30: RCT 15x5 | E30: ? | F30: N | G30: 15 | H30: 5 | I30: CF | J30: 0 | K30: 2 | L30: 75 | M30: =L30/K30 -> 37.5 | N30: http://www.rc-drones.com
B32: Sigma | C32: CF Prop | D32: S 12x3.8 | E32: 6.3mm | F32: N | G32: 12 | H32: 3.8 | I32: CF | J32: 15.4 | K32: 2 | L32: 20 | M32: =L32/K32 -> 10 | N32: http://www.hobby-wing.com
B33: Sigma | C33: CF Prop | D33: S 13x4.0 | E33: 4.0mm | F33: N | G33: 13 | H33: 4 | I33: CF | J33: 0 | K33: 2 | L33: 20 | M33: =L33/K33 -> 10 | N33: http://www.hobby-wing.com
B34: Sigma | C34: CF Prop | D34: S 15x4.0 | E34: 4.0mm | F34: N | G34: 15 | H34: 4 | I34: CF | J34: 17 | K34: 2 | L34: 29.99 | M34: =L34/K34 -> 14.995 | N34: http://www.hobby-wing.com
B35: Sigma | C35: Multicopter | D35: S 15x5.5 | E35: T Style | F35: N | G35: 15 | H35: 5.5 | I35: CF | J35: 0 | K35: 2 | L35: 35 | M35: =L35/K35 -> 17.5 | N35: http://www.hobby-wing.com
B36: Sigma | C36: Multicopter | D36: S 17x5.5 | E36: T Style | F36: N | G36: 17 | H36: 5.5 | I36: CF | J36: 0 | K36: 2 | L36: 45 | M36: =L36/K36 -> 22.5 | N36: http://www.hobby-wing.com/
A38: 14 | B38: Tarot | C38: HE CF TL Series Prop | D38: T 12x5.5 | E38: T Style | F38: N | G38: 12 | H38: 5.5 | I38: CF | J38: 11.2 | K38: 2 | L38: 15 | M38: =L38/K38 -> 7.5 | N38: http://www.hobby-wing.com
A39: 15 | B39: Tarot | C39: HE CF TL Series Prop | D39: T 13x5.5 | E39: T Style | F39: N | G39: 13 | H39: 5.5 | I39: CF | J39: 14 | K39: 2 | L39: 18 | M39: =L39/K39 -> 9 | N39: http://www.hobby-wing.com
A40: 16 | B40: Tarot | C40: HE CF TL Series Prop | D40: T 15x5.5 | E40: T Style | F40: N | G40: 15 | H40: 5.5 | I40: CF | J40: 18.2 | K40: 2 | L40: 25 | M40: =L40/K40 -> 12.5 | N40: http://www.hobby-wing.com
A41: 17 | B41: Tarot | C41: HE CF TL Series Prop | D41: T 16x5.5 | E41: T Style | F41: N | G41: 16 | H41: 5.5 | I41: CF | J41: 23 | K41: 2 | L41: 28 | M41: =L41/K41 -> 14 | N41: http://www.hobby-wing.com
A42: 1 | B42: Tarot | C42: HE CF Prop | D42: T 17x5.5 | E42: T Style | F42: N | G42: 17 | H42: 5.5 | I42: CF | J42: 0 | K42: 2 | L42: 35 | M42: =L42/K42 -> 17.5 | N42: http://www.hobby-wing.com
B44: Round 1:
B45: Skipped
B47: Round 2:
B48: 12 <= Prop <= 16
B49: High Price
...

Sheet 11. Accessories
A1: Accessories
A2: Options for GPS Accessories | B2: Brand | C2: Line | D2: Model | E2: Battery Life Span | F2: Smartphone/Tablet/Computer Trackable? | G2: Height (mm) | H2: Width (mm) | I2: Thickness (mm) | J2: Waterproof? | K2: Mass (grams) | L2: Line Power | M2: Power Source | N2: Service Plan Required? | O2: Subscription Price | P2: Duration | Q2: Product Price | R2: Total Price with 1 year subscription (USD) | S2: Link
